Workbook

Sheet SUMMARY
B1: In-House Wood Control
B3: Conclusion
B4: ="1. Wood received: "&TEXT(F17,"0.00")&" m³, Rp "&TEXT(F18,"#,##0")&"." -> 1. Wood received: 227.34 m³, Rp 1,512,843,233.
B5: ="2. Wood inventory: Rp "&TEXT(F42,"#,##0")&", consisting of board stock and WIP in-house. Shipped to Plant 1: Rp "&TEXT(F45,"#,##0")&"." -> 2. Wood inventory: Rp 279,614,925, consisting of board stock and WIP in-house. Shipped to Plant 1: Rp 1,233,228,308.
B6: ="3. Wood used per chair: "&TEXT(F35,"0.0000")&" m³ against a benchmark of "&TEXT(F36,"0.0000")&" m³. Wood cost per chair: Rp "&TEXT(F37,"#,##0")&"." -> 3. Wood used per chair: 0.0493 m³ against a benchmark of 0.0500 m³. Wood cost per chair: Rp 328,510.
B7: =_xlfn.LET(_xlpm.t,SUMIFS(OUT!$F$14:$F$5084,OUT!$L$14:$L$5084,"Adjustment"),_xlpm.p,SUMIFS(OUT!$O$14:$O$5084,OUT!$L$14:$L$5084,"Adjustment",OUT!$B$14:$B$5084,"<"&'OUT Since Sep'!$B$1)+SUMIFS(OUT!$F$14:$F$5084,OUT!$P$14:$P$5084,"Explained",OUT!$N$14:$N$5084,"",OUT!$B$14:$B$5084,"<"&'OUT Since Sep'!$B$1),"4. Stock adjustment without a usage record: "&TEXT(_xlpm.t,"0.00")&" m³ ("&TEXT(_xlpm.t/F26,"0%")&" of wood used). Before Sep (Edy era, missed records): "&TEXT(_xlpm.p,"0.00")&" m³. Since Sep: "&TEXT(_xlpm.t-_xlpm.p,"0.00")&" m³. "&IF(F35<=F36,"Wood used per chair is within benchmark, so the adjustment is accepted, but its use in production or as scrap cannot be verified.","Wood used per chair is above benchmark, and the use of the adjustment in production or as scrap cannot be verified.")) -> 4. Stock adjustment without a usage record: 28.81 m³ (14% of wood used). Before Sep (Edy era, missed records): 28.61 m³. Since Sep: 0.20 m³. Wood used per chair is within benchmark, so the adjustment is accepted, but its use in production or as scrap cannot be verified.
B8: ="5. Without a BoM per product, overuse on individual products or MOs cannot be identified, even when the overall average is within benchmark." -> 5. Without a BoM per product, overuse on individual products or MOs cannot be identified, even when the overall average is within benchmark.
B9: ="6. Required: a complete record of every wood issue, and a BoM per product." -> 6. Required: a complete record of every wood issue, and a BoM per product.
B11: Input | G11: Basis
B12: Wood benchmark per chair (m³) | C12: 0.05 | G12: Assumption
B13: Seater-only counted as (chair) | C13: 0.1 | G13: Assumption
B15: Description | C15: Teak | D15: Sungkai | E15: Pine | F15: Total | G15: Basis | J15: Zero check
B16: 1. Wood received
B17: Volume (m³) | C17: =SUMIFS(IN!$G$2:$G$5001,IN!$D$2:$D$5001,"Teak",IN!$J$2:$J$5001,"Received") -> 148.16234 | D17: =SUMIFS(IN!$G$2:$G$5001,IN!$D$2:$D$5001,"Sungkai",IN!$J$2:$J$5001,"Received") -> 78.193031 | E17: =SUMIFS(IN!$G$2:$G$5001,IN!$D$2:$D$5001,"Pine",IN!$J$2:$J$5001,"Received") -> 0.9839 | F17: =SUM(C17:E17) -> 227.33927 | G17: Data | J17: =ROUND(F17-SUMIFS(IN!$G$2:$G$5001,IN!$J$2:$J$5001,"Received"),6) -> 0
B18: Value (Rp) | C18: =SUMIFS(IN!$H$2:$H$5001,IN!$D$2:$D$5001,"Teak",IN!$J$2:$J$5001,"Received") -> 1.1146335e+09 | D18: =SUMIFS(IN!$H$2:$H$5001,IN!$D$2:$D$5001,"Sungkai",IN!$J$2:$J$5001,"Received") -> 3.9515967e+08 | E18: =SUMIFS(IN!$H$2:$H$5001,IN!$D$2:$D$5001,"Pine",IN!$J$2:$J$5001,"Received") -> 3050090 | F18: =SUM(C18:E18) -> 1.5128432e+09 | G18: Data | J18: =ROUND(F18-SUMIFS(IN!$H$2:$H$5001,IN!$J$2:$J$5001,"Received"),0) -> 0
B19: Average price per m³ (Rp) | C19: =IF(C17=0,0,C18/C17) -> 7523055.5 | D19: =IF(D17=0,0,D18/D17) -> 5053643.1 | E19: =IF(E17=0,0,E18/E17) -> 3100000 | F19: =IF(F17=0,0,F18/F17) -> 6654561.9 | G19: Calculated
B21: 2. Board stock (book)
B22: Volume (m³) | C22: =SUMIFS(STOK!$M$5:$M$5002,STOK!$A$5:$A$5002,"Teak") -> 16.12396 | D22: =SUMIFS(STOK!$M$5:$M$5002,STOK!$A$5:$A$5002,"Sungkai") -> 9.930121 | E22: =SUMIFS(STOK!$M$5:$M$5002,STOK!$A$5:$A$5002,"Pine") -> 0.12218 | F22: =SUM(C22:E22) -> 26.176261 | G22: Calculated | J22: =ROUND(F22-STOK!$M$32,6) -> 0
B23: Value (Rp) | C23: =C22*C19 -> 1.2130145e+08 | D23: =D22*D19 -> 50183287 | E23: =E22*E19 -> 378758 | F23: =SUM(C23:E23) -> 1.7186349e+08 | G23: Calculated | J23: =ROUND(F23-SUMPRODUCT(C22:E22,C19:E19),0) -> 0
B25: 3. Wood used
B26: Volume (m³) | C26: =C17-C22 -> 132.03838 | D26: =D17-D22 -> 68.26291 | E26: =E17-E22 -> 0.86172 | F26: =SUM(C26:E26) -> 201.16301 | G26: Calculated | J26: =ROUND(F26-SUM(OUT!$F$14:$F$5084),6) -> 0
B27: Value (Rp) | C27: =C18-C23 -> 9.9333203e+08 | D27: =D18-D23 -> 3.4497638e+08 | E27: =E18-E23 -> 2671332 | F27: =SUM(C27:E27) -> 1.3409797e+09 | G27: Calculated | J27: =ROUND(F27-(F18-F23),0) -> 0
B29: 4. Chairs
B30: Chairs cut | C30: =SUMIFS(REALDATA!$O$2:$O$1048576,REALDATA!$K$2:$K$1048576,"Teak") -> 3106 | D30: =SUMIFS(REALDATA!$O$2:$O$1048576,REALDATA!$K$2:$K$1048576,"Sungkai") -> 961 | E30: =SUMIFS(REALDATA!$O$2:$O$1048576,REALDATA!$K$2:$K$1048576,"Pinus") -> 15 | F30: =SUM(C30:E30) -> 4082 | G30: Calculated | J30: =ROUND(F30-SUM(REALDATA!$O$2:$O$1048576),6) -> 0
B31: Shipped to Plant 1 | C31: =SUMIFS(REALDATA!$V$2:$V$1048576,REALDATA!$K$2:$K$1048576,"Teak") -> 2811 | D31: =SUMIFS(REALDATA!$V$2:$V$1048576,REALDATA!$K$2:$K$1048576,"Sungkai") -> 943 | E31: =SUMIFS(REALDATA!$V$2:$V$1048576,REALDATA!$K$2:$K$1048576,"Pinus") -> 0 | F31: =SUM(C31:E31) -> 3754 | G31: Calculated | J31: =ROUND(F31-SUM(REALDATA!$V$2:$V$1048576),6) -> 0
B32: WIP in-house | C32: =C30-C31 -> 295 | D32: =D30-D31 -> 18 | E32: =E30-E31 -> 15 | F32: =SUM(C32:E32) -> 328 | G32: Calculated | J32: =ROUND(F32-(F30-F31),6) -> 0
B34: 5. Per chair
B35: Wood used per chair (m³) | F35: =IF(F30=0,0,F26/F30) -> 0.049280501 | G35: Calculated
B36: Benchmark per chair (m³) | F36: =$C$12 -> 0.05 | G36: Assumption
B37: Wood cost per chair (Rp) | F37: =IF(F30=0,0,F27/F30) -> 328510.47 | G37: Calculated
B39: 6. Wood inventory (Rp)
B40: Board stock | F40: =F23 -> 1.7186349e+08 | G40: Calculated
B41: WIP in-house | F41: =F32*F37 -> 1.0775143e+08 | G41: Calculated
B42: Total wood inventory | F42: =F40+F41 -> 2.7961493e+08 | G42: Calculated | J42: =ROUND(F42-(F40+F41),0) -> 0
B44: 7. Shipped to Plant 1 (Rp)
B45: Shipped to Plant 1 | F45: =F27-F41 -> 1.2332283e+09 | G45: Calculated | J45: =ROUND(F45+F42-F18,0) -> 0
B47: 8. Wood stock as of 24 Oct (m³)
B48: Thickness (cm) | C48: Teak | D48: Sungkai | E48: Pine | F48: Total
B49: 2 | C49: =SUMIFS(STOK!$M$5:$M$29,STOK!$A$5:$A$29,C$48,STOK!$B$5:$B$29,$B49) -> 0.00736 | D49: =SUMIFS(STOK!$M$5:$M$29,STOK!$A$5:$A$29,D$48,STOK!$B$5:$B$29,$B49) -> 0 | E49: =SUMIFS(STOK!$M$5:$M$29,STOK!$A$5:$A$29,E$48,STOK!$B$5:$B$29,$B49) -> 0 | F49: =SUM(C49:E49) -> 0.00736
B50: 2.5 | C50: =SUMIFS(STOK!$M$5:$M$29,STOK!$A$5:$A$29,C$48,STOK!$B$5:$B$29,$B50) -> 0 | D50: =SUMIFS(STOK!$M$5:$M$29,STOK!$A$5:$A$29,D$48,STOK!$B$5:$B$29,$B50) -> 0.078225 | E50: =SUMIFS(STOK!$M$5:$M$29,STOK!$A$5:$A$29,E$48,STOK!$B$5:$B$29,$B50) -> 0.034505 | F50: =SUM(C50:E50) -> 0.11273
...

Sheet STOK
A1: Board Stock by Thickness
A2: ="As of "&TEXT(MAX(OUT!$B$14:$B$5084),"dd-mmm-yyyy") -> As of 24-Oct-2026
A3: Wood Type | B3: Thickness (cm) | C3: Mov. From | D3: Opening Count 14-Oct-2026 | F3: In | H3: Out | J3: Adj | L3: Book Balance | N3: Notes | O3: Latest Count Date | P3: Latest Count | R3: Variance (Book − Count)
D4: pcs | E4: m³ | F4: pcs | G4: m³ | H4: pcs | I4: m³ | J4: pcs | K4: m³ | L4: pcs | M4: m³ | P4: pcs | Q4: m³ | R4: pcs | S4: m³
A5: Teak | B5: 2 | C5: 46310 | D5: =SUMIFS('OPNAME LOG'!$D$2:$D$1000,'OPNAME LOG'!$A$2:$A$1000,DATE(2026,10,14),'OPNAME LOG'!$B$2:$B$1000,IF($A5="Teak","Jati",IF($A5="Pine","Pinus",$A5)),'OPNAME LOG'!$C$2:$C$1000,$B5)+SUMIFS('OPNAME LOG'!$D$2:$D$1000,'OPNAME LOG'!$A$2:$A$1000,DATE(2026,10,14),'OPNAME LOG'!$B$2:$B$1000,IF($A5="Teak","Jati",IF($A5="Pine","Pinus",$A5)),'OPNAME LOG'!$C$2:$C$1000,$B5&" (Grade A)") -> 6 | E5: =SUMIFS('OPNAME LOG'!$E$2:$E$1000,'OPNAME LOG'!$A$2:$A$1000,DATE(2026,10,14),'OPNAME LOG'!$B$2:$B$1000,IF($A5="Teak","Jati",IF($A5="Pine","Pinus",$A5)),'OPNAME LOG'!$C$2:$C$1000,$B5)+SUMIFS('OPNAME LOG'!$E$2:$E$1000,'OPNAME LOG'!$A$2:$A$1000,DATE(2026,10,14),'OPNAME LOG'!$B$2:$B$1000,IF($A5="Teak","Jati",IF($A5="Pine","Pinus",$A5)),'OPNAME LOG'!$C$2:$C$1000,$B5&" (Grade A)") -> 0.02136 | F5: =SUMIFS(INCOMING!$E$2:$E$5000,INCOMING!$C$2:$C$5000,$A5,INCOMING!$D$2:$D$5000,$B5,INCOMING!$B$2:$B$5000,">="&$C5) -> 0 | G5: =SUMIFS(INCOMING!$F$2:$F$5000,INCOMING!$C$2:$C$5000,$A5,INCOMING!$D$2:$D$5000,$B5,INCOMING!$B$2:$B$5000,">="&$C5) -> 0 | H5: =SUMIFS(OUT!$E$14:$E$5084,OUT!$C$14:$C$5084,$A5,OUT!$D$14:$D$5084,$B5,OUT!$B$14:$B$5084,">="&$C5,OUT!$L$14:$L$5084,"<>Adjustment") -> 2 | I5: =SUMIFS(OUT!$F$14:$F$5084,OUT!$C$14:$C$5084,$A5,OUT!$D$14:$D$5084,$B5,OUT!$B$14:$B$5084,">="&$C5,OUT!$L$14:$L$5084,"<>Adjustment") -> 0.014 | J5: =SUMIFS(OUT!$E$14:$E$5084,OUT!$C$14:$C$5084,$A5,OUT!$D$14:$D$5084,$B5,OUT!$B$14:$B$5084,">="&$C5,OUT!$L$14:$L$5084,"Adjustment") -> 0 | K5: =SUMIFS(OUT!$F$14:$F$5084,OUT!$C$14:$C$5084,$A5,OUT!$D$14:$D$5084,$B5,OUT!$B$14:$B$5084,">="&$C5,OUT!$L$14:$L$5084,"Adjustment") -> 0 | L5: =D5+F5-H5-J5 -> 4 | M5: =E5+G5-I5-K5 -> 0.00736 | O5: =_xlfn.MAXIFS('OPNAME LOG'!$A$2:$A$1000,'OPNAME LOG'!$B$2:$B$1000,IF($A5="Teak","Jati",IF($A5="Pine","Pinus",$A5)),'OPNAME LOG'!$C$2:$C$1000,$B5) -> 46319 | P5: =SUMIFS('OPNAME LOG'!$D$2:$D$1000,'OPNAME LOG'!$A$2:$A$1000,$O5,'OPNAME LOG'!$B$2:$B$1000,IF($A5="Teak","Jati",IF($A5="Pine","Pinus",$A5)),'OPNAME LOG'!$C$2:$C$1000,$B5)+SUMIFS('OPNAME LOG'!$D$2:$D$1000,'OPNAME LOG'!$A$2:$A$1000,$O5,'OPNAME LOG'!$B$2:$B$1000,IF($A5="Teak","Jati",IF($A5="Pine","Pinus",$A5)),'OPNAME LOG'!$C$2:$C$1000,$B5&" (Grade A)") -> 3.9808 | Q5: =SUMIFS('OPNAME LOG'!$E$2:$E$1000,'OPNAME LOG'!$A$2:$A$1000,$O5,'OPNAME LOG'!$B$2:$B$1000,IF($A5="Teak","Jati",IF($A5="Pine","Pinus",$A5)),'OPNAME LOG'!$C$2:$C$1000,$B5)+SUMIFS('OPNAME LOG'!$E$2:$E$1000,'OPNAME LOG'!$A$2:$A$1000,$O5,'OPNAME LOG'!$B$2:$B$1000,IF($A5="Teak","Jati",IF($A5="Pine","Pinus",$A5)),'OPNAME LOG'!$C$2:$C$1000,$B5&" (Grade A)") -> 0.00736 | R5: =ROUND(L5-P5,6) -> 0.0192 | S5: =ROUND(M5-Q5,6) -> 0
A6: Teak | B6: 3 | C6: 46310 | D6: =SUMIFS('OPNAME LOG'!$D$2:$D$1000,'OPNAME LOG'!$A$2:$A$1000,DATE(2026,10,14),'OPNAME LOG'!$B$2:$B$1000,IF($A6="Teak","Jati",IF($A6="Pine","Pinus",$A6)),'OPNAME LOG'!$C$2:$C$1000,$B6)+SUMIFS('OPNAME LOG'!$D$2:$D$1000,'OPNAME LOG'!$A$2:$A$1000,DATE(2026,10,14),'OPNAME LOG'!$B$2:$B$1000,IF($A6="Teak","Jati",IF($A6="Pine","Pinus",$A6)),'OPNAME LOG'!$C$2:$C$1000,$B6&" (Grade A)") -> 1 | E6: =SUMIFS('OPNAME LOG'!$E$2:$E$1000,'OPNAME LOG'!$A$2:$A$1000,DATE(2026,10,14),'OPNAME LOG'!$B$2:$B$1000,IF($A6="Teak","Jati",IF($A6="Pine","Pinus",$A6)),'OPNAME LOG'!$C$2:$C$1000,$B6)+SUMIFS('OPNAME LOG'!$E$2:$E$1000,'OPNAME LOG'!$A$2:$A$1000,DATE(2026,10,14),'OPNAME LOG'!$B$2:$B$1000,IF($A6="Teak","Jati",IF($A6="Pine","Pinus",$A6)),'OPNAME LOG'!$C$2:$C$1000,$B6&" (Grade A)") -> 0.0102 | F6: =SUMIFS(INCOMING!$E$2:$E$5000,INCOMING!$C$2:$C$5000,$A6,INCOMING!$D$2:$D$5000,$B6,INCOMING!$B$2:$B$5000,">="&$C6) -> 0 | G6: =SUMIFS(INCOMING!$F$2:$F$5000,INCOMING!$C$2:$C$5000,$A6,INCOMING!$D$2:$D$5000,$B6,INCOMING!$B$2:$B$5000,">="&$C6) -> 0 | H6: =SUMIFS(OUT!$E$14:$E$5084,OUT!$C$14:$C$5084,$A6,OUT!$D$14:$D$5084,$B6,OUT!$B$14:$B$5084,">="&$C6,OUT!$L$14:$L$5084,"<>Adjustment") -> 2 | I6: =SUMIFS(OUT!$F$14:$F$5084,OUT!$C$14:$C$5084,$A6,OUT!$D$14:$D$5084,$B6,OUT!$B$14:$B$5084,">="&$C6,OUT!$L$14:$L$5084,"<>Adjustment") -> 0.0192 | J6: =SUMIFS(OUT!$E$14:$E$5084,OUT!$C$14:$C$5084,$A6,OUT!$D$14:$D$5084,$B6,OUT!$B$14:$B$5084,">="&$C6,OUT!$L$14:$L$5084,"Adjustment") -> 0 | K6: =SUMIFS(OUT!$F$14:$F$5084,OUT!$C$14:$C$5084,$A6,OUT!$D$14:$D$5084,$B6,OUT!$B$14:$B$5084,">="&$C6,OUT!$L$14:$L$5084,"Adjustment") -> 0 | L6: =D6+F6-H6-J6 -> -1 | M6: =E6+G6-I6-K6 -> -0.009 | O6: =_xlfn.MAXIFS('OPNAME LOG'!$A$2:$A$1000,'OPNAME LOG'!$B$2:$B$1000,IF($A6="Teak","Jati",IF($A6="Pine","Pinus",$A6)),'OPNAME LOG'!$C$2:$C$1000,$B6) -> 46319 | P6: =SUMIFS('OPNAME LOG'!$D$2:$D$1000,'OPNAME LOG'!$A$2:$A$1000,$O6,'OPNAME LOG'!$B$2:$B$1000,IF($A6="Teak","Jati",IF($A6="Pine","Pinus",$A6)),'OPNAME LOG'!$C$2:$C$1000,$B6)+SUMIFS('OPNAME LOG'!$D$2:$D$1000,'OPNAME LOG'!$A$2:$A$1000,$O6,'OPNAME LOG'!$B$2:$B$1000,IF($A6="Teak","Jati",IF($A6="Pine","Pinus",$A6)),'OPNAME LOG'!$C$2:$C$1000,$B6&" (Grade A)") -> 1 | Q6: =SUMIFS('OPNAME LOG'!$E$2:$E$1000,'OPNAME LOG'!$A$2:$A$1000,$O6,'OPNAME LOG'!$B$2:$B$1000,IF($A6="Teak","Jati",IF($A6="Pine","Pinus",$A6)),'OPNAME LOG'!$C$2:$C$1000,$B6)+SUMIFS('OPNAME LOG'!$E$2:$E$1000,'OPNAME LOG'!$A$2:$A$1000,$O6,'OPNAME LOG'!$B$2:$B$1000,IF($A6="Teak","Jati",IF($A6="Pine","Pinus",$A6)),'OPNAME LOG'!$C$2:$C$1000,$B6&" (Grade A)") -> 0.0102 | R6: =ROUND(L6-P6,6) -> -2 | S6: =ROUND(M6-Q6,6) -> -0.0192
A7: Teak | B7: 3.5 | C7: 46310 | D7: =SUMIFS('OPNAME LOG'!$D$2:$D$1000,'OPNAME LOG'!$A$2:$A$1000,DATE(2026,10,14),'OPNAME LOG'!$B$2:$B$1000,IF($A7="Teak","Jati",IF($A7="Pine","Pinus",$A7)),'OPNAME LOG'!$C$2:$C$1000,$B7)+SUMIFS('OPNAME LOG'!$D$2:$D$1000,'OPNAME LOG'!$A$2:$A$1000,DATE(2026,10,14),'OPNAME LOG'!$B$2:$B$1000,IF($A7="Teak","Jati",IF($A7="Pine","Pinus",$A7)),'OPNAME LOG'!$C$2:$C$1000,$B7&" (Grade A)") -> 99 | E7: =SUMIFS('OPNAME LOG'!$E$2:$E$1000,'OPNAME LOG'!$A$2:$A$1000,DATE(2026,10,14),'OPNAME LOG'!$B$2:$B$1000,IF($A7="Teak","Jati",IF($A7="Pine","Pinus",$A7)),'OPNAME LOG'!$C$2:$C$1000,$B7)+SUMIFS('OPNAME LOG'!$E$2:$E$1000,'OPNAME LOG'!$A$2:$A$1000,DATE(2026,10,14),'OPNAME LOG'!$B$2:$B$1000,IF($A7="Teak","Jati",IF($A7="Pine","Pinus",$A7)),'OPNAME LOG'!$C$2:$C$1000,$B7&" (Grade A)") -> 1.039465 | F7: =SUMIFS(INCOMING!$E$2:$E$5000,INCOMING!$C$2:$C$5000,$A7,INCOMING!$D$2:$D$5000,$B7,INCOMING!$B$2:$B$5000,">="&$C7) -> 316 | G7: =SUMIFS(INCOMING!$F$2:$F$5000,INCOMING!$C$2:$C$5000,$A7,INCOMING!$D$2:$D$5000,$B7,INCOMING!$B$2:$B$5000,">="&$C7) -> 2.95407 | H7: =SUMIFS(OUT!$E$14:$E$5084,OUT!$C$14:$C$5084,$A7,OUT!$D$14:$D$5084,$B7,OUT!$B$14:$B$5084,">="&$C7,OUT!$L$14:$L$5084,"<>Adjustment") -> 173 | I7: =SUMIFS(OUT!$F$14:$F$5084,OUT!$C$14:$C$5084,$A7,OUT!$D$14:$D$5084,$B7,OUT!$B$14:$B$5084,">="&$C7,OUT!$L$14:$L$5084,"<>Adjustment") -> 1.740025 | J7: =SUMIFS(OUT!$E$14:$E$5084,OUT!$C$14:$C$5084,$A7,OUT!$D$14:$D$5084,$B7,OUT!$B$14:$B$5084,">="&$C7,OUT!$L$14:$L$5084,"Adjustment") -> 0 | K7: =SUMIFS(OUT!$F$14:$F$5084,OUT!$C$14:$C$5084,$A7,OUT!$D$14:$D$5084,$B7,OUT!$B$14:$B$5084,">="&$C7,OUT!$L$14:$L$5084,"Adjustment") -> 0 | L7: =D7+F7-H7-J7 -> 242 | M7: =E7+G7-I7-K7 -> 2.25351 | O7: =_xlfn.MAXIFS('OPNAME LOG'!$A$2:$A$1000,'OPNAME LOG'!$B$2:$B$1000,IF($A7="Teak","Jati",IF($A7="Pine","Pinus",$A7)),'OPNAME LOG'!$C$2:$C$1000,$B7) -> 46319 | P7: =SUMIFS('OPNAME LOG'!$D$2:$D$1000,'OPNAME LOG'!$A$2:$A$1000,$O7,'OPNAME LOG'!$B$2:$B$1000,IF($A7="Teak","Jati",IF($A7="Pine","Pinus",$A7)),'OPNAME LOG'!$C$2:$C$1000,$B7)+SUMIFS('OPNAME LOG'!$D$2:$D$1000,'OPNAME LOG'!$A$2:$A$1000,$O7,'OPNAME LOG'!$B$2:$B$1000,IF($A7="Teak","Jati",IF($A7="Pine","Pinus",$A7)),'OPNAME LOG'!$C$2:$C$1000,$B7&" (Grade A)") -> 242 | Q7: =SUMIFS('OPNAME LOG'!$E$2:$E$1000,'OPNAME LOG'!$A$2:$A$1000,$O7,'OPNAME LOG'!$B$2:$B$1000,IF($A7="Teak","Jati",IF($A7="Pine","Pinus",$A7)),'OPNAME LOG'!$C$2:$C$1000,$B7)+SUMIFS('OPNAME LOG'!$E$2:$E$1000,'OPNAME LOG'!$A$2:$A$1000,$O7,'OPNAME LOG'!$B$2:$B$1000,IF($A7="Teak","Jati",IF($A7="Pine","Pinus",$A7)),'OPNAME LOG'!$C$2:$C$1000,$B7&" (Grade A)") -> 2.13171 | R7: =ROUND(L7-P7,6) -> 0 | S7: =ROUND(M7-Q7,6) -> 0.1218
A8: Teak | B8: 4 | C8: 46310 | D8: =SUMIFS('OPNAME LOG'!$D$2:$D$1000,'OPNAME LOG'!$A$2:$A$1000,DATE(2026,10,14),'OPNAME LOG'!$B$2:$B$1000,IF($A8="Teak","Jati",IF($A8="Pine","Pinus",$A8)),'OPNAME LOG'!$C$2:$C$1000,$B8)+SUMIFS('OPNAME LOG'!$D$2:$D$1000,'OPNAME LOG'!$A$2:$A$1000,DATE(2026,10,14),'OPNAME LOG'!$B$2:$B$1000,IF($A8="Teak","Jati",IF($A8="Pine","Pinus",$A8)),'OPNAME LOG'!$C$2:$C$1000,$B8&" (Grade A)") -> 1 | E8: =SUMIFS('OPNAME LOG'!$E$2:$E$1000,'OPNAME LOG'!$A$2:$A$1000,DATE(2026,10,14),'OPNAME LOG'!$B$2:$B$1000,IF($A8="Teak","Jati",IF($A8="Pine","Pinus",$A8)),'OPNAME LOG'!$C$2:$C$1000,$B8)+SUMIFS('OPNAME LOG'!$E$2:$E$1000,'OPNAME LOG'!$A$2:$A$1000,DATE(2026,10,14),'OPNAME LOG'!$B$2:$B$1000,IF($A8="Teak","Jati",IF($A8="Pine","Pinus",$A8)),'OPNAME LOG'!$C$2:$C$1000,$B8&" (Grade A)") -> 0.0144 | F8: =SUMIFS(INCOMING!$E$2:$E$5000,INCOMING!$C$2:$C$5000,$A8,INCOMING!$D$2:$D$5000,$B8,INCOMING!$B$2:$B$5000,">="&$C8) -> 0 | G8: =SUMIFS(INCOMING!$F$2:$F$5000,INCOMING!$C$2:$C$5000,$A8,INCOMING!$D$2:$D$5000,$B8,INCOMING!$B$2:$B$5000,">="&$C8) -> 0 | H8: =SUMIFS(OUT!$E$14:$E$5084,OUT!$C$14:$C$5084,$A8,OUT!$D$14:$D$5084,$B8,OUT!$B$14:$B$5084,">="&$C8,OUT!$L$14:$L$5084,"<>Adjustment") -> 0 | I8: =SUMIFS(OUT!$F$14:$F$5084,OUT!$C$14:$C$5084,$A8,OUT!$D$14:$D$5084,$B8,OUT!$B$14:$B$5084,">="&$C8,OUT!$L$14:$L$5084,"<>Adjustment") -> 0 | J8: =SUMIFS(OUT!$E$14:$E$5084,OUT!$C$14:$C$5084,$A8,OUT!$D$14:$D$5084,$B8,OUT!$B$14:$B$5084,">="&$C8,OUT!$L$14:$L$5084,"Adjustment") -> 0 | K8: =SUMIFS(OUT!$F$14:$F$5084,OUT!$C$14:$C$5084,$A8,OUT!$D$14:$D$5084,$B8,OUT!$B$14:$B$5084,">="&$C8,OUT!$L$14:$L$5084,"Adjustment") -> 0 | L8: =D8+F8-H8-J8 -> 1 | M8: =E8+G8-I8-K8 -> 0.0144 | O8: =_xlfn.MAXIFS('OPNAME LOG'!$A$2:$A$1000,'OPNAME LOG'!$B$2:$B$1000,IF($A8="Teak","Jati",IF($A8="Pine","Pinus",$A8)),'OPNAME LOG'!$C$2:$C$1000,$B8) -> 46319 | P8: =SUMIFS('OPNAME LOG'!$D$2:$D$1000,'OPNAME LOG'!$A$2:$A$1000,$O8,'OPNAME LOG'!$B$2:$B$1000,IF($A8="Teak","Jati",IF($A8="Pine","Pinus",$A8)),'OPNAME LOG'!$C$2:$C$1000,$B8)+SUMIFS('OPNAME LOG'!$D$2:$D$1000,'OPNAME LOG'!$A$2:$A$1000,$O8,'OPNAME LOG'!$B$2:$B$1000,IF($A8="Teak","Jati",IF($A8="Pine","Pinus",$A8)),'OPNAME LOG'!$C$2:$C$1000,$B8&" (Grade A)") -> 1 | Q8: =SUMIFS('OPNAME LOG'!$E$2:$E$1000,'OPNAME LOG'!$A$2:$A$1000,$O8,'OPNAME LOG'!$B$2:$B$1000,IF($A8="Teak","Jati",IF($A8="Pine","Pinus",$A8)),'OPNAME LOG'!$C$2:$C$1000,$B8)+SUMIFS('OPNAME LOG'!$E$2:$E$1000,'OPNAME LOG'!$A$2:$A$1000,$O8,'OPNAME LOG'!$B$2:$B$1000,IF($A8="Teak","Jati",IF($A8="Pine","Pinus",$A8)),'OPNAME LOG'!$C$2:$C$1000,$B8&" (Grade A)") -> 0.0144 | R8: =ROUND(L8-P8,6) -> 0 | S8: =ROUND(M8-Q8,6) -> 0
A9: Teak | B9: 4.5 | C9: 46310 | D9: =SUMIFS('OPNAME LOG'!$D$2:$D$1000,'OPNAME LOG'!$A$2:$A$1000,DATE(2026,10,14),'OPNAME LOG'!$B$2:$B$1000,IF($A9="Teak","Jati",IF($A9="Pine","Pinus",$A9)),'OPNAME LOG'!$C$2:$C$1000,$B9)+SUMIFS('OPNAME LOG'!$D$2:$D$1000,'OPNAME LOG'!$A$2:$A$1000,DATE(2026,10,14),'OPNAME LOG'!$B$2:$B$1000,IF($A9="Teak","Jati",IF($A9="Pine","Pinus",$A9)),'OPNAME LOG'!$C$2:$C$1000,$B9&" (Grade A)") -> 167 | E9: =SUMIFS('OPNAME LOG'!$E$2:$E$1000,'OPNAME LOG'!$A$2:$A$1000,DATE(2026,10,14),'OPNAME LOG'!$B$2:$B$1000,IF($A9="Teak","Jati",IF($A9="Pine","Pinus",$A9)),'OPNAME LOG'!$C$2:$C$1000,$B9)+SUMIFS('OPNAME LOG'!$E$2:$E$1000,'OPNAME LOG'!$A$2:$A$1000,DATE(2026,10,14),'OPNAME LOG'!$B$2:$B$1000,IF($A9="Teak","Jati",IF($A9="Pine","Pinus",$A9)),'OPNAME LOG'!$C$2:$C$1000,$B9&" (Grade A)") -> 2.80422 | F9: =SUMIFS(INCOMING!$E$2:$E$5000,INCOMING!$C$2:$C$5000,$A9,INCOMING!$D$2:$D$5000,$B9,INCOMING!$B$2:$B$5000,">="&$C9) -> 123 | G9: =SUMIFS(INCOMING!$F$2:$F$5000,INCOMING!$C$2:$C$5000,$A9,INCOMING!$D$2:$D$5000,$B9,INCOMING!$B$2:$B$5000,">="&$C9) -> 1.997415 | H9: =SUMIFS(OUT!$E$14:$E$5084,OUT!$C$14:$C$5084,$A9,OUT!$D$14:$D$5084,$B9,OUT!$B$14:$B$5084,">="&$C9,OUT!$L$14:$L$5084,"<>Adjustment") -> 245 | I9: =SUMIFS(OUT!$F$14:$F$5084,OUT!$C$14:$C$5084,$A9,OUT!$D$14:$D$5084,$B9,OUT!$B$14:$B$5084,">="&$C9,OUT!$L$14:$L$5084,"<>Adjustment") -> 4.065795 | J9: =SUMIFS(OUT!$E$14:$E$5084,OUT!$C$14:$C$5084,$A9,OUT!$D$14:$D$5084,$B9,OUT!$B$14:$B$5084,">="&$C9,OUT!$L$14:$L$5084,"Adjustment") -> 0 | K9: =SUMIFS(OUT!$F$14:$F$5084,OUT!$C$14:$C$5084,$A9,OUT!$D$14:$D$5084,$B9,OUT!$B$14:$B$5084,">="&$C9,OUT!$L$14:$L$5084,"Adjustment") -> 0 | L9: =D9+F9-H9-J9 -> 45 | M9: =E9+G9-I9-K9 -> 0.73584 | O9: =_xlfn.MAXIFS('OPNAME LOG'!$A$2:$A$1000,'OPNAME LOG'!$B$2:$B$1000,IF($A9="Teak","Jati",IF($A9="Pine","Pinus",$A9)),'OPNAME LOG'!$C$2:$C$1000,$B9) -> 46319 | P9: =SUMIFS('OPNAME LOG'!$D$2:$D$1000,'OPNAME LOG'!$A$2:$A$1000,$O9,'OPNAME LOG'!$B$2:$B$1000,IF($A9="Teak","Jati",IF($A9="Pine","Pinus",$A9)),'OPNAME LOG'!$C$2:$C$1000,$B9)+SUMIFS('OPNAME LOG'!$D$2:$D$1000,'OPNAME LOG'!$A$2:$A$1000,$O9,'OPNAME LOG'!$B$2:$B$1000,IF($A9="Teak","Jati",IF($A9="Pine","Pinus",$A9)),'OPNAME LOG'!$C$2:$C$1000,$B9&" (Grade A)") -> 57 | Q9: =SUMIFS('OPNAME LOG'!$E$2:$E$1000,'OPNAME LOG'!$A$2:$A$1000,$O9,'OPNAME LOG'!$B$2:$B$1000,IF($A9="Teak","Jati",IF($A9="Pine","Pinus",$A9)),'OPNAME LOG'!$C$2:$C$1000,$B9)+SUMIFS('OPNAME LOG'!$E$2:$E$1000,'OPNAME LOG'!$A$2:$A$1000,$O9,'OPNAME LOG'!$B$2:$B$1000,IF($A9="Teak","Jati",IF($A9="Pine","Pinus",$A9)),'OPNAME LOG'!$C$2:$C$1000,$B9&" (Grade A)") -> 0.846945 | R9: =ROUND(L9-P9,6) -> -12 | S9: =ROUND(M9-Q9,6) -> -0.111105
A10: Teak | B10: 5 | C10: 46310 | D10: =SUMIFS('OPNAME LOG'!$D$2:$D$1000,'OPNAME LOG'!$A$2:$A$1000,DATE(2026,10,14),'OPNAME LOG'!$B$2:$B$1000,IF($A10="Teak","Jati",IF($A10="Pine","Pinus",$A10)),'OPNAME LOG'!$C$2:$C$1000,$B10)+SUMIFS('OPNAME LOG'!$D$2:$D$1000,'OPNAME LOG'!$A$2:$A$1000,DATE(2026,10,14),'OPNAME LOG'!$B$2:$B$1000,IF($A10="Teak","Jati",IF($A10="Pine","Pinus",$A10)),'OPNAME LOG'!$C$2:$C$1000,$B10&" (Grade A)") -> 1 | E10: =SUMIFS('OPNAME LOG'!$E$2:$E$1000,'OPNAME LOG'!$A$2:$A$1000,DATE(2026,10,14),'OPNAME LOG'!$B$2:$B$1000,IF($A10="Teak","Jati",IF($A10="Pine","Pinus",$A10)),'OPNAME LOG'!$C$2:$C$1000,$B10)+SUMIFS('OPNAME LOG'!$E$2:$E$1000,'OPNAME LOG'!$A$2:$A$1000,DATE(2026,10,14),'OPNAME LOG'!$B$2:$B$1000,IF($A10="Teak","Jati",IF($A10="Pine","Pinus",$A10)),'OPNAME LOG'!$C$2:$C$1000,$B10&" (Grade A)") -> 0 | F10: =SUMIFS(INCOMING!$E$2:$E$5000,INCOMING!$C$2:$C$5000,$A10,INCOMING!$D$2:$D$5000,$B10,INCOMING!$B$2:$B$5000,">="&$C10) -> 0 | G10: =SUMIFS(INCOMING!$F$2:$F$5000,INCOMING!$C$2:$C$5000,$A10,INCOMING!$D$2:$D$5000,$B10,INCOMING!$B$2:$B$5000,">="&$C10) -> 0 | H10: =SUMIFS(OUT!$E$14:$E$5084,OUT!$C$14:$C$5084,$A10,OUT!$D$14:$D$5084,$B10,OUT!$B$14:$B$5084,">="&$C10,OUT!$L$14:$L$5084,"<>Adjustment") -> 0 | I10: =SUMIFS(OUT!$F$14:$F$5084,OUT!$C$14:$C$5084,$A10,OUT!$D$14:$D$5084,$B10,OUT!$B$14:$B$5084,">="&$C10,OUT!$L$14:$L$5084,"<>Adjustment") -> 0 | J10: =SUMIFS(OUT!$E$14:$E$5084,OUT!$C$14:$C$5084,$A10,OUT!$D$14:$D$5084,$B10,OUT!$B$14:$B$5084,">="&$C10,OUT!$L$14:$L$5084,"Adjustment") -> 0 | K10: =SUMIFS(OUT!$F$14:$F$5084,OUT!$C$14:$C$5084,$A10,OUT!$D$14:$D$5084,$B10,OUT!$B$14:$B$5084,">="&$C10,OUT!$L$14:$L$5084,"Adjustment") -> 0 | L10: =D10+F10-H10-J10 -> 1 | M10: =E10+G10-I10-K10 -> 0 | N10: Out 0.371 m³ exceeds count 0.351 m³. 1 pcs not yet measured. | O10: =_xlfn.MAXIFS('OPNAME LOG'!$A$2:$A$1000,'OPNAME LOG'!$B$2:$B$1000,IF($A10="Teak","Jati",IF($A10="Pine","Pinus",$A10)),'OPNAME LOG'!$C$2:$C$1000,$B10) -> 46319 | P10: =SUMIFS('OPNAME LOG'!$D$2:$D$1000,'OPNAME LOG'!$A$2:$A$1000,$O10,'OPNAME LOG'!$B$2:$B$1000,IF($A10="Teak","Jati",IF($A10="Pine","Pinus",$A10)),'OPNAME LOG'!$C$2:$C$1000,$B10)+SUMIFS('OPNAME LOG'!$D$2:$D$1000,'OPNAME LOG'!$A$2:$A$1000,$O10,'OPNAME LOG'!$B$2:$B$1000,IF($A10="Teak","Jati",IF($A10="Pine","Pinus",$A10)),'OPNAME LOG'!$C$2:$C$1000,$B10&" (Grade A)") -> 0 | Q10: =SUMIFS('OPNAME LOG'!$E$2:$E$1000,'OPNAME LOG'!$A$2:$A$1000,$O10,'OPNAME LOG'!$B$2:$B$1000,IF($A10="Teak","Jati",IF($A10="Pine","Pinus",$A10)),'OPNAME LOG'!$C$2:$C$1000,$B10)+SUMIFS('OPNAME LOG'!$E$2:$E$1000,'OPNAME LOG'!$A$2:$A$1000,$O10,'OPNAME LOG'!$B$2:$B$1000,IF($A10="Teak","Jati",IF($A10="Pine","Pinus",$A10)),'OPNAME LOG'!$C$2:$C$1000,$B10&" (Grade A)") -> 0 | R10: =ROUND(L10-P10,6) -> 1 | S10: =ROUND(M10-Q10,6) -> 0
A11: Teak | B11: 5.5 | C11: 46310 | D11: =SUMIFS('OPNAME LOG'!$D$2:$D$1000,'OPNAME LOG'!$A$2:$A$1000,DATE(2026,10,14),'OPNAME LOG'!$B$2:$B$1000,IF($A11="Teak","Jati",IF($A11="Pine","Pinus",$A11)),'OPNAME LOG'!$C$2:$C$1000,$B11)+SUMIFS('OPNAME LOG'!$D$2:$D$1000,'OPNAME LOG'!$A$2:$A$1000,DATE(2026,10,14),'OPNAME LOG'!$B$2:$B$1000,IF($A11="Teak","Jati",IF($A11="Pine","Pinus",$A11)),'OPNAME LOG'!$C$2:$C$1000,$B11&" (Grade A)") -> 0 | E11: =SUMIFS('OPNAME LOG'!$E$2:$E$1000,'OPNAME LOG'!$A$2:$A$1000,DATE(2026,10,14),'OPNAME LOG'!$B$2:$B$1000,IF($A11="Teak","Jati",IF($A11="Pine","Pinus",$A11)),'OPNAME LOG'!$C$2:$C$1000,$B11)+SUMIFS('OPNAME LOG'!$E$2:$E$1000,'OPNAME LOG'!$A$2:$A$1000,DATE(2026,10,14),'OPNAME LOG'!$B$2:$B$1000,IF($A11="Teak","Jati",IF($A11="Pine","Pinus",$A11)),'OPNAME LOG'!$C$2:$C$1000,$B11&" (Grade A)") -> 0 | F11: =SUMIFS(INCOMING!$E$2:$E$5000,INCOMING!$C$2:$C$5000,$A11,INCOMING!$D$2:$D$5000,$B11,INCOMING!$B$2:$B$5000,">="&$C11) -> 0 | G11: =SUMIFS(INCOMING!$F$2:$F$5000,INCOMING!$C$2:$C$5000,$A11,INCOMING!$D$2:$D$5000,$B11,INCOMING!$B$2:$B$5000,">="&$C11) -> 0 | H11: =SUMIFS(OUT!$E$14:$E$5084,OUT!$C$14:$C$5084,$A11,OUT!$D$14:$D$5084,$B11,OUT!$B$14:$B$5084,">="&$C11,OUT!$L$14:$L$5084,"<>Adjustment") -> 0 | I11: =SUMIFS(OUT!$F$14:$F$5084,OUT!$C$14:$C$5084,$A11,OUT!$D$14:$D$5084,$B11,OUT!$B$14:$B$5084,">="&$C11,OUT!$L$14:$L$5084,"<>Adjustment") -> 0 | J11: =SUMIFS(OUT!$E$14:$E$5084,OUT!$C$14:$C$5084,$A11,OUT!$D$14:$D$5084,$B11,OUT!$B$14:$B$5084,">="&$C11,OUT!$L$14:$L$5084,"Adjustment") -> 0 | K11: =SUMIFS(OUT!$F$14:$F$5084,OUT!$C$14:$C$5084,$A11,OUT!$D$14:$D$5084,$B11,OUT!$B$14:$B$5084,">="&$C11,OUT!$L$14:$L$5084,"Adjustment") -> 0 | L11: =D11+F11-H11-J11 -> 0 | M11: =E11+G11-I11-K11 -> 0 | O11: =_xlfn.MAXIFS('OPNAME LOG'!$A$2:$A$1000,'OPNAME LOG'!$B$2:$B$1000,IF($A11="Teak","Jati",IF($A11="Pine","Pinus",$A11)),'OPNAME LOG'!$C$2:$C$1000,$B11) -> 46319 | P11: =SUMIFS('OPNAME LOG'!$D$2:$D$1000,'OPNAME LOG'!$A$2:$A$1000,$O11,'OPNAME LOG'!$B$2:$B$1000,IF($A11="Teak","Jati",IF($A11="Pine","Pinus",$A11)),'OPNAME LOG'!$C$2:$C$1000,$B11)+SUMIFS('OPNAME LOG'!$D$2:$D$1000,'OPNAME LOG'!$A$2:$A$1000,$O11,'OPNAME LOG'!$B$2:$B$1000,IF($A11="Teak","Jati",IF($A11="Pine","Pinus",$A11)),'OPNAME LOG'!$C$2:$C$1000,$B11&" (Grade A)") -> 0 | Q11: =SUMIFS('OPNAME LOG'!$E$2:$E$1000,'OPNAME LOG'!$A$2:$A$1000,$O11,'OPNAME LOG'!$B$2:$B$1000,IF($A11="Teak","Jati",IF($A11="Pine","Pinus",$A11)),'OPNAME LOG'!$C$2:$C$1000,$B11)+SUMIFS('OPNAME LOG'!$E$2:$E$1000,'OPNAME LOG'!$A$2:$A$1000,$O11,'OPNAME LOG'!$B$2:$B$1000,IF($A11="Teak","Jati",IF($A11="Pine","Pinus",$A11)),'OPNAME LOG'!$C$2:$C$1000,$B11&" (Grade A)") -> 0 | R11: =ROUND(L11-P11,6) -> 0 | S11: =ROUND(M11-Q11,6) -> 0
A12: Teak | B12: 6 | C12: 46310 | D12: =SUMIFS('OPNAME LOG'!$D$2:$D$1000,'OPNAME LOG'!$A$2:$A$1000,DATE(2026,10,14),'OPNAME LOG'!$B$2:$B$1000,IF($A12="Teak","Jati",IF($A12="Pine","Pinus",$A12)),'OPNAME LOG'!$C$2:$C$1000,$B12)+SUMIFS('OPNAME LOG'!$D$2:$D$1000,'OPNAME LOG'!$A$2:$A$1000,DATE(2026,10,14),'OPNAME LOG'!$B$2:$B$1000,IF($A12="Teak","Jati",IF($A12="Pine","Pinus",$A12)),'OPNAME LOG'!$C$2:$C$1000,$B12&" (Grade A)") -> 240.9808 | E12: =SUMIFS('OPNAME LOG'!$E$2:$E$1000,'OPNAME LOG'!$A$2:$A$1000,DATE(2026,10,14),'OPNAME LOG'!$B$2:$B$1000,IF($A12="Teak","Jati",IF($A12="Pine","Pinus",$A12)),'OPNAME LOG'!$C$2:$C$1000,$B12)+SUMIFS('OPNAME LOG'!$E$2:$E$1000,'OPNAME LOG'!$A$2:$A$1000,DATE(2026,10,14),'OPNAME LOG'!$B$2:$B$1000,IF($A12="Teak","Jati",IF($A12="Pine","Pinus",$A12)),'OPNAME LOG'!$C$2:$C$1000,$B12&" (Grade A)") -> 5.36976 | F12: =SUMIFS(INCOMING!$E$2:$E$5000,INCOMING!$C$2:$C$5000,$A12,INCOMING!$D$2:$D$5000,$B12,INCOMING!$B$2:$B$5000,">="&$C12) -> 0 | G12: =SUMIFS(INCOMING!$F$2:$F$5000,INCOMING!$C$2:$C$5000,$A12,INCOMING!$D$2:$D$5000,$B12,INCOMING!$B$2:$B$5000,">="&$C12) -> 0 | H12: =SUMIFS(OUT!$E$14:$E$5084,OUT!$C$14:$C$5084,$A12,OUT!$D$14:$D$5084,$B12,OUT!$B$14:$B$5084,">="&$C12,OUT!$L$14:$L$5084,"<>Adjustment") -> 33 | I12: =SUMIFS(OUT!$F$14:$F$5084,OUT!$C$14:$C$5084,$A12,OUT!$D$14:$D$5084,$B12,OUT!$B$14:$B$5084,">="&$C12,OUT!$L$14:$L$5084,"<>Adjustment") -> 0.83052 | J12: =SUMIFS(OUT!$E$14:$E$5084,OUT!$C$14:$C$5084,$A12,OUT!$D$14:$D$5084,$B12,OUT!$B$14:$B$5084,">="&$C12,OUT!$L$14:$L$5084,"Adjustment") -> 0 | K12: =SUMIFS(OUT!$F$14:$F$5084,OUT!$C$14:$C$5084,$A12,OUT!$D$14:$D$5084,$B12,OUT!$B$14:$B$5084,">="&$C12,OUT!$L$14:$L$5084,"Adjustment") -> 0 | L12: =D12+F12-H12-J12 -> 207.9808 | M12: =E12+G12-I12-K12 -> 4.53924 | O12: =_xlfn.MAXIFS('OPNAME LOG'!$A$2:$A$1000,'OPNAME LOG'!$B$2:$B$1000,IF($A12="Teak","Jati",IF($A12="Pine","Pinus",$A12)),'OPNAME LOG'!$C$2:$C$1000,$B12) -> 46319 | P12: =SUMIFS('OPNAME LOG'!$D$2:$D$1000,'OPNAME LOG'!$A$2:$A$1000,$O12,'OPNAME LOG'!$B$2:$B$1000,IF($A12="Teak","Jati",IF($A12="Pine","Pinus",$A12)),'OPNAME LOG'!$C$2:$C$1000,$B12)+SUMIFS('OPNAME LOG'!$D$2:$D$1000,'OPNAME LOG'!$A$2:$A$1000,$O12,'OPNAME LOG'!$B$2:$B$1000,IF($A12="Teak","Jati",IF($A12="Pine","Pinus",$A12)),'OPNAME LOG'!$C$2:$C$1000,$B12&" (Grade A)") -> 222.74343 | Q12: =SUMIFS('OPNAME LOG'!$E$2:$E$1000,'OPNAME LOG'!$A$2:$A$1000,$O12,'OPNAME LOG'!$B$2:$B$1000,IF($A12="Teak","Jati",IF($A12="Pine","Pinus",$A12)),'OPNAME LOG'!$C$2:$C$1000,$B12)+SUMIFS('OPNAME LOG'!$E$2:$E$1000,'OPNAME LOG'!$A$2:$A$1000,$O12,'OPNAME LOG'!$B$2:$B$1000,IF($A12="Teak","Jati",IF($A12="Pine","Pinus",$A12)),'OPNAME LOG'!$C$2:$C$1000,$B12&" (Grade A)") -> 5.03256 | R12: =ROUND(L12-P12,6) -> -14.762625 | S12: =ROUND(M12-Q12,6) -> -0.49332
A13: Teak | B13: 7 | C13: 46310 | D13: =SUMIFS('OPNAME LOG'!$D$2:$D$1000,'OPNAME LOG'!$A$2:$A$1000,DATE(2026,10,14),'OPNAME LOG'!$B$2:$B$1000,IF($A13="Teak","Jati",IF($A13="Pine","Pinus",$A13)),'OPNAME LOG'!$C$2:$C$1000,$B13)+SUMIFS('OPNAME LOG'!$D$2:$D$1000,'OPNAME LOG'!$A$2:$A$1000,DATE(2026,10,14),'OPNAME LOG'!$B$2:$B$1000,IF($A13="Teak","Jati",IF($A13="Pine","Pinus",$A13)),'OPNAME LOG'!$C$2:$C$1000,$B13&" (Grade A)") -> 263 | E13: =SUMIFS('OPNAME LOG'!$E$2:$E$1000,'OPNAME LOG'!$A$2:$A$1000,DATE(2026,10,14),'OPNAME LOG'!$B$2:$B$1000,IF($A13="Teak","Jati",IF($A13="Pine","Pinus",$A13)),'OPNAME LOG'!$C$2:$C$1000,$B13)+SUMIFS('OPNAME LOG'!$E$2:$E$1000,'OPNAME LOG'!$A$2:$A$1000,DATE(2026,10,14),'OPNAME LOG'!$B$2:$B$1000,IF($A13="Teak","Jati",IF($A13="Pine","Pinus",$A13)),'OPNAME LOG'!$C$2:$C$1000,$B13&" (Grade A)") -> 7.51863 | F13: =SUMIFS(INCOMING!$E$2:$E$5000,INCOMING!$C$2:$C$5000,$A13,INCOMING!$D$2:$D$5000,$B13,INCOMING!$B$2:$B$5000,">="&$C13) -> 0 | G13: =SUMIFS(INCOMING!$F$2:$F$5000,INCOMING!$C$2:$C$5000,$A13,INCOMING!$D$2:$D$5000,$B13,INCOMING!$B$2:$B$5000,">="&$C13) -> 0 | H13: =SUMIFS(OUT!$E$14:$E$5084,OUT!$C$14:$C$5084,$A13,OUT!$D$14:$D$5084,$B13,OUT!$B$14:$B$5084,">="&$C13,OUT!$L$14:$L$5084,"<>Adjustment") -> 42 | I13: =SUMIFS(OUT!$F$14:$F$5084,OUT!$C$14:$C$5084,$A13,OUT!$D$14:$D$5084,$B13,OUT!$B$14:$B$5084,">="&$C13,OUT!$L$14:$L$5084,"<>Adjustment") -> 1.3013 | J13: =SUMIFS(OUT!$E$14:$E$5084,OUT!$C$14:$C$5084,$A13,OUT!$D$14:$D$5084,$B13,OUT!$B$14:$B$5084,">="&$C13,OUT!$L$14:$L$5084,"Adjustment") -> 0 | K13: =SUMIFS(OUT!$F$14:$F$5084,OUT!$C$14:$C$5084,$A13,OUT!$D$14:$D$5084,$B13,OUT!$B$14:$B$5084,">="&$C13,OUT!$L$14:$L$5084,"Adjustment") -> 0 | L13: =D13+F13-H13-J13 -> 221 | M13: =E13+G13-I13-K13 -> 6.21733 | O13: =_xlfn.MAXIFS('OPNAME LOG'!$A$2:$A$1000,'OPNAME LOG'!$B$2:$B$1000,IF($A13="Teak","Jati",IF($A13="Pine","Pinus",$A13)),'OPNAME LOG'!$C$2:$C$1000,$B13) -> 46319 | P13: =SUMIFS('OPNAME LOG'!$D$2:$D$1000,'OPNAME LOG'!$A$2:$A$1000,$O13,'OPNAME LOG'!$B$2:$B$1000,IF($A13="Teak","Jati",IF($A13="Pine","Pinus",$A13)),'OPNAME LOG'!$C$2:$C$1000,$B13)+SUMIFS('OPNAME LOG'!$D$2:$D$1000,'OPNAME LOG'!$A$2:$A$1000,$O13,'OPNAME LOG'!$B$2:$B$1000,IF($A13="Teak","Jati",IF($A13="Pine","Pinus",$A13)),'OPNAME LOG'!$C$2:$C$1000,$B13&" (Grade A)") -> 41 | Q13: =SUMIFS('OPNAME LOG'!$E$2:$E$1000,'OPNAME LOG'!$A$2:$A$1000,$O13,'OPNAME LOG'!$B$2:$B$1000,IF($A13="Teak","Jati",IF($A13="Pine","Pinus",$A13)),'OPNAME LOG'!$C$2:$C$1000,$B13)+SUMIFS('OPNAME LOG'!$E$2:$E$1000,'OPNAME LOG'!$A$2:$A$1000,$O13,'OPNAME LOG'!$B$2:$B$1000,IF($A13="Teak","Jati",IF($A13="Pine","Pinus",$A13)),'OPNAME LOG'!$C$2:$C$1000,$B13&" (Grade A)") -> 6.982416 | R13: =ROUND(L13-P13,6) -> 180 | S13: =ROUND(M13-Q13,6) -> -0.765086
A14: Teak | B14: 8 | C14: 46310 | D14: =SUMIFS('OPNAME LOG'!$D$2:$D$1000,'OPNAME LOG'!$A$2:$A$1000,DATE(2026,10,14),'OPNAME LOG'!$B$2:$B$1000,IF($A14="Teak","Jati",IF($A14="Pine","Pinus",$A14)),'OPNAME LOG'!$C$2:$C$1000,$B14)+SUMIFS('OPNAME LOG'!$D$2:$D$1000,'OPNAME LOG'!$A$2:$A$1000,DATE(2026,10,14),'OPNAME LOG'!$B$2:$B$1000,IF($A14="Teak","Jati",IF($A14="Pine","Pinus",$A14)),'OPNAME LOG'!$C$2:$C$1000,$B14&" (Grade A)") -> 75 | E14: =SUMIFS('OPNAME LOG'!$E$2:$E$1000,'OPNAME LOG'!$A$2:$A$1000,DATE(2026,10,14),'OPNAME LOG'!$B$2:$B$1000,IF($A14="Teak","Jati",IF($A14="Pine","Pinus",$A14)),'OPNAME LOG'!$C$2:$C$1000,$B14)+SUMIFS('OPNAME LOG'!$E$2:$E$1000,'OPNAME LOG'!$A$2:$A$1000,DATE(2026,10,14),'OPNAME LOG'!$B$2:$B$1000,IF($A14="Teak","Jati",IF($A14="Pine","Pinus",$A14)),'OPNAME LOG'!$C$2:$C$1000,$B14&" (Grade A)") -> 2.36528 | F14: =SUMIFS(INCOMING!$E$2:$E$5000,INCOMING!$C$2:$C$5000,$A14,INCOMING!$D$2:$D$5000,$B14,INCOMING!$B$2:$B$5000,">="&$C14) -> 0 | G14: =SUMIFS(INCOMING!$F$2:$F$5000,INCOMING!$C$2:$C$5000,$A14,INCOMING!$D$2:$D$5000,$B14,INCOMING!$B$2:$B$5000,">="&$C14) -> 0 | H14: =SUMIFS(OUT!$E$14:$E$5084,OUT!$C$14:$C$5084,$A14,OUT!$D$14:$D$5084,$B14,OUT!$B$14:$B$5084,">="&$C14,OUT!$L$14:$L$5084,"<>Adjustment") -> 0 | I14: =SUMIFS(OUT!$F$14:$F$5084,OUT!$C$14:$C$5084,$A14,OUT!$D$14:$D$5084,$B14,OUT!$B$14:$B$5084,">="&$C14,OUT!$L$14:$L$5084,"<>Adjustment") -> 0 | J14: =SUMIFS(OUT!$E$14:$E$5084,OUT!$C$14:$C$5084,$A14,OUT!$D$14:$D$5084,$B14,OUT!$B$14:$B$5084,">="&$C14,OUT!$L$14:$L$5084,"Adjustment") -> 0 | K14: =SUMIFS(OUT!$F$14:$F$5084,OUT!$C$14:$C$5084,$A14,OUT!$D$14:$D$5084,$B14,OUT!$B$14:$B$5084,">="&$C14,OUT!$L$14:$L$5084,"Adjustment") -> 0 | L14: =D14+F14-H14-J14 -> 75 | M14: =E14+G14-I14-K14 -> 2.36528 | O14: =_xlfn.MAXIFS('OPNAME LOG'!$A$2:$A$1000,'OPNAME LOG'!$B$2:$B$1000,IF($A14="Teak","Jati",IF($A14="Pine","Pinus",$A14)),'OPNAME LOG'!$C$2:$C$1000,$B14) -> 46319 | P14: =SUMIFS('OPNAME LOG'!$D$2:$D$1000,'OPNAME LOG'!$A$2:$A$1000,$O14,'OPNAME LOG'!$B$2:$B$1000,IF($A14="Teak","Jati",IF($A14="Pine","Pinus",$A14)),'OPNAME LOG'!$C$2:$C$1000,$B14)+SUMIFS('OPNAME LOG'!$D$2:$D$1000,'OPNAME LOG'!$A$2:$A$1000,$O14,'OPNAME LOG'!$B$2:$B$1000,IF($A14="Teak","Jati",IF($A14="Pine","Pinus",$A14)),'OPNAME LOG'!$C$2:$C$1000,$B14&" (Grade A)") -> 74 | Q14: =SUMIFS('OPNAME LOG'!$E$2:$E$1000,'OPNAME LOG'!$A$2:$A$1000,$O14,'OPNAME LOG'!$B$2:$B$1000,IF($A14="Teak","Jati",IF($A14="Pine","Pinus",$A14)),'OPNAME LOG'!$C$2:$C$1000,$B14)+SUMIFS('OPNAME LOG'!$E$2:$E$1000,'OPNAME LOG'!$A$2:$A$1000,$O14,'OPNAME LOG'!$B$2:$B$1000,IF($A14="Teak","Jati",IF($A14="Pine","Pinus",$A14)),'OPNAME LOG'!$C$2:$C$1000,$B14&" (Grade A)") -> 2.30008 | R14: =ROUND(L14-P14,6) -> 1 | S14: =ROUND(M14-Q14,6) -> 0.0652
A15: Total Teak | D15: =SUM(D5:D14) -> 853.9808 | E15: =SUM(E5:E14) -> 19.143315 | F15: =SUM(F5:F14) -> 439 | G15: =SUM(G5:G14) -> 4.951485 | H15: =SUM(H5:H14) -> 497 | I15: =SUM(I5:I14) -> 7.97084 | J15: =SUM(J5:J14) -> 0 | K15: =SUM(K5:K14) -> 0 | ... M15: =SUM(M5:M14) -> 16.12396 | P15: =SUM(P5:P14) -> 642.72422 | Q15: =SUM(Q5:Q14) -> 17.325671 | R15: =SUM(R5:R14) -> 153.25657 | S15: =SUM(S5:S14) -> -1.201711
A17: Sungkai | B17: 2.5 | C17: 46310 | D17: =SUMIFS('OPNAME LOG'!$D$2:$D$1000,'OPNAME LOG'!$A$2:$A$1000,DATE(2026,10,14),'OPNAME LOG'!$B$2:$B$1000,IF($A17="Teak","Jati",IF($A17="Pine","Pinus",$A17)),'OPNAME LOG'!$C$2:$C$1000,$B17)+SUMIFS('OPNAME LOG'!$D$2:$D$1000,'OPNAME LOG'!$A$2:$A$1000,DATE(2026,10,14),'OPNAME LOG'!$B$2:$B$1000,IF($A17="Teak","Jati",IF($A17="Pine","Pinus",$A17)),'OPNAME LOG'!$C$2:$C$1000,$B17&" (Grade A)") -> 18 | E17: =SUMIFS('OPNAME LOG'!$E$2:$E$1000,'OPNAME LOG'!$A$2:$A$1000,DATE(2026,10,14),'OPNAME LOG'!$B$2:$B$1000,IF($A17="Teak","Jati",IF($A17="Pine","Pinus",$A17)),'OPNAME LOG'!$C$2:$C$1000,$B17)+SUMIFS('OPNAME LOG'!$E$2:$E$1000,'OPNAME LOG'!$A$2:$A$1000,DATE(2026,10,14),'OPNAME LOG'!$B$2:$B$1000,IF($A17="Teak","Jati",IF($A17="Pine","Pinus",$A17)),'OPNAME LOG'!$C$2:$C$1000,$B17&" (Grade A)") -> 0.078225 | F17: =SUMIFS(INCOMING!$E$2:$E$5000,INCOMING!$C$2:$C$5000,$A17,INCOMING!$D$2:$D$5000,$B17,INCOMING!$B$2:$B$5000,">="&$C17) -> 0 | G17: =SUMIFS(INCOMING!$F$2:$F$5000,INCOMING!$C$2:$C$5000,$A17,INCOMING!$D$2:$D$5000,$B17,INCOMING!$B$2:$B$5000,">="&$C17) -> 0 | H17: =SUMIFS(OUT!$E$14:$E$5084,OUT!$C$14:$C$5084,$A17,OUT!$D$14:$D$5084,$B17,OUT!$B$14:$B$5084,">="&$C17,OUT!$L$14:$L$5084,"<>Adjustment") -> 0 | I17: =SUMIFS(OUT!$F$14:$F$5084,OUT!$C$14:$C$5084,$A17,OUT!$D$14:$D$5084,$B17,OUT!$B$14:$B$5084,">="&$C17,OUT!$L$14:$L$5084,"<>Adjustment") -> 0 | J17: =SUMIFS(OUT!$E$14:$E$5084,OUT!$C$14:$C$5084,$A17,OUT!$D$14:$D$5084,$B17,OUT!$B$14:$B$5084,">="&$C17,OUT!$L$14:$L$5084,"Adjustment") -> 0 | K17: =SUMIFS(OUT!$F$14:$F$5084,OUT!$C$14:$C$5084,$A17,OUT!$D$14:$D$5084,$B17,OUT!$B$14:$B$5084,">="&$C17,OUT!$L$14:$L$5084,"Adjustment") -> 0 | L17: =D17+F17-H17-J17 -> 18 | M17: =E17+G17-I17-K17 -> 0.078225 | O17: =_xlfn.MAXIFS('OPNAME LOG'!$A$2:$A$1000,'OPNAME LOG'!$B$2:$B$1000,IF($A17="Teak","Jati",IF($A17="Pine","Pinus",$A17)),'OPNAME LOG'!$C$2:$C$1000,$B17) -> 46319 | P17: =SUMIFS('OPNAME LOG'!$D$2:$D$1000,'OPNAME LOG'!$A$2:$A$1000,$O17,'OPNAME LOG'!$B$2:$B$1000,IF($A17="Teak","Jati",IF($A17="Pine","Pinus",$A17)),'OPNAME LOG'!$C$2:$C$1000,$B17)+SUMIFS('OPNAME LOG'!$D$2:$D$1000,'OPNAME LOG'!$A$2:$A$1000,$O17,'OPNAME LOG'!$B$2:$B$1000,IF($A17="Teak","Jati",IF($A17="Pine","Pinus",$A17)),'OPNAME LOG'!$C$2:$C$1000,$B17&" (Grade A)") -> 18 | Q17: =SUMIFS('OPNAME LOG'!$E$2:$E$1000,'OPNAME LOG'!$A$2:$A$1000,$O17,'OPNAME LOG'!$B$2:$B$1000,IF($A17="Teak","Jati",IF($A17="Pine","Pinus",$A17)),'OPNAME LOG'!$C$2:$C$1000,$B17)+SUMIFS('OPNAME LOG'!$E$2:$E$1000,'OPNAME LOG'!$A$2:$A$1000,$O17,'OPNAME LOG'!$B$2:$B$1000,IF($A17="Teak","Jati",IF($A17="Pine","Pinus",$A17)),'OPNAME LOG'!$C$2:$C$1000,$B17&" (Grade A)") -> 0.078225 | R17: =ROUND(L17-P17,6) -> 0 | S17: =ROUND(M17-Q17,6) -> 0
A18: Sungkai | B18: 3 | C18: 46310 | D18: =SUMIFS('OPNAME LOG'!$D$2:$D$1000,'OPNAME LOG'!$A$2:$A$1000,DATE(2026,10,14),'OPNAME LOG'!$B$2:$B$1000,IF($A18="Teak","Jati",IF($A18="Pine","Pinus",$A18)),'OPNAME LOG'!$C$2:$C$1000,$B18)+SUMIFS('OPNAME LOG'!$D$2:$D$1000,'OPNAME LOG'!$A$2:$A$1000,DATE(2026,10,14),'OPNAME LOG'!$B$2:$B$1000,IF($A18="Teak","Jati",IF($A18="Pine","Pinus",$A18)),'OPNAME LOG'!$C$2:$C$1000,$B18&" (Grade A)") -> 300 | E18: =SUMIFS('OPNAME LOG'!$E$2:$E$1000,'OPNAME LOG'!$A$2:$A$1000,DATE(2026,10,14),'OPNAME LOG'!$B$2:$B$1000,IF($A18="Teak","Jati",IF($A18="Pine","Pinus",$A18)),'OPNAME LOG'!$C$2:$C$1000,$B18)+SUMIFS('OPNAME LOG'!$E$2:$E$1000,'OPNAME LOG'!$A$2:$A$1000,DATE(2026,10,14),'OPNAME LOG'!$B$2:$B$1000,IF($A18="Teak","Jati",IF($A18="Pine","Pinus",$A18)),'OPNAME LOG'!$C$2:$C$1000,$B18&" (Grade A)") -> 1.694871 | F18: =SUMIFS(INCOMING!$E$2:$E$5000,INCOMING!$C$2:$C$5000,$A18,INCOMING!$D$2:$D$5000,$B18,INCOMING!$B$2:$B$5000,">="&$C18) -> 0 | G18: =SUMIFS(INCOMING!$F$2:$F$5000,INCOMING!$C$2:$C$5000,$A18,INCOMING!$D$2:$D$5000,$B18,INCOMING!$B$2:$B$5000,">="&$C18) -> 0 | H18: =SUMIFS(OUT!$E$14:$E$5084,OUT!$C$14:$C$5084,$A18,OUT!$D$14:$D$5084,$B18,OUT!$B$14:$B$5084,">="&$C18,OUT!$L$14:$L$5084,"<>Adjustment") -> 45 | I18: =SUMIFS(OUT!$F$14:$F$5084,OUT!$C$14:$C$5084,$A18,OUT!$D$14:$D$5084,$B18,OUT!$B$14:$B$5084,">="&$C18,OUT!$L$14:$L$5084,"<>Adjustment") -> 0.30759 | J18: =SUMIFS(OUT!$E$14:$E$5084,OUT!$C$14:$C$5084,$A18,OUT!$D$14:$D$5084,$B18,OUT!$B$14:$B$5084,">="&$C18,OUT!$L$14:$L$5084,"Adjustment") -> 0 | K18: =SUMIFS(OUT!$F$14:$F$5084,OUT!$C$14:$C$5084,$A18,OUT!$D$14:$D$5084,$B18,OUT!$B$14:$B$5084,">="&$C18,OUT!$L$14:$L$5084,"Adjustment") -> 0 | L18: =D18+F18-H18-J18 -> 255 | M18: =E18+G18-I18-K18 -> 1.387281 | O18: =_xlfn.MAXIFS('OPNAME LOG'!$A$2:$A$1000,'OPNAME LOG'!$B$2:$B$1000,IF($A18="Teak","Jati",IF($A18="Pine","Pinus",$A18)),'OPNAME LOG'!$C$2:$C$1000,$B18) -> 46319 | P18: =SUMIFS('OPNAME LOG'!$D$2:$D$1000,'OPNAME LOG'!$A$2:$A$1000,$O18,'OPNAME LOG'!$B$2:$B$1000,IF($A18="Teak","Jati",IF($A18="Pine","Pinus",$A18)),'OPNAME LOG'!$C$2:$C$1000,$B18)+SUMIFS('OPNAME LOG'!$D$2:$D$1000,'OPNAME LOG'!$A$2:$A$1000,$O18,'OPNAME LOG'!$B$2:$B$1000,IF($A18="Teak","Jati",IF($A18="Pine","Pinus",$A18)),'OPNAME LOG'!$C$2:$C$1000,$B18&" (Grade A)") -> 254.88354 | Q18: =SUMIFS('OPNAME LOG'!$E$2:$E$1000,'OPNAME LOG'!$A$2:$A$1000,$O18,'OPNAME LOG'!$B$2:$B$1000,IF($A18="Teak","Jati",IF($A18="Pine","Pinus",$A18)),'OPNAME LOG'!$C$2:$C$1000,$B18)+SUMIFS('OPNAME LOG'!$E$2:$E$1000,'OPNAME LOG'!$A$2:$A$1000,$O18,'OPNAME LOG'!$B$2:$B$1000,IF($A18="Teak","Jati",IF($A18="Pine","Pinus",$A18)),'OPNAME LOG'!$C$2:$C$1000,$B18&" (Grade A)") -> 1.387281 | R18: =ROUND(L18-P18,6) -> 0.11646 | S18: =ROUND(M18-Q18,6) -> 0
A19: Sungkai | B19: 3.5 | C19: 46310 | D19: =SUMIFS('OPNAME LOG'!$D$2:$D$1000,'OPNAME LOG'!$A$2:$A$1000,DATE(2026,10,14),'OPNAME LOG'!$B$2:$B$1000,IF($A19="Teak","Jati",IF($A19="Pine","Pinus",$A19)),'OPNAME LOG'!$C$2:$C$1000,$B19)+SUMIFS('OPNAME LOG'!$D$2:$D$1000,'OPNAME LOG'!$A$2:$A$1000,DATE(2026,10,14),'OPNAME LOG'!$B$2:$B$1000,IF($A19="Teak","Jati",IF($A19="Pine","Pinus",$A19)),'OPNAME LOG'!$C$2:$C$1000,$B19&" (Grade A)") -> 338 | E19: =SUMIFS('OPNAME LOG'!$E$2:$E$1000,'OPNAME LOG'!$A$2:$A$1000,DATE(2026,10,14),'OPNAME LOG'!$B$2:$B$1000,IF($A19="Teak","Jati",IF($A19="Pine","Pinus",$A19)),'OPNAME LOG'!$C$2:$C$1000,$B19)+SUMIFS('OPNAME LOG'!$E$2:$E$1000,'OPNAME LOG'!$A$2:$A$1000,DATE(2026,10,14),'OPNAME LOG'!$B$2:$B$1000,IF($A19="Teak","Jati",IF($A19="Pine","Pinus",$A19)),'OPNAME LOG'!$C$2:$C$1000,$B19&" (Grade A)") -> 2.763775 | F19: =SUMIFS(INCOMING!$E$2:$E$5000,INCOMING!$C$2:$C$5000,$A19,INCOMING!$D$2:$D$5000,$B19,INCOMING!$B$2:$B$5000,">="&$C19) -> 0 | G19: =SUMIFS(INCOMING!$F$2:$F$5000,INCOMING!$C$2:$C$5000,$A19,INCOMING!$D$2:$D$5000,$B19,INCOMING!$B$2:$B$5000,">="&$C19) -> 0 | H19: =SUMIFS(OUT!$E$14:$E$5084,OUT!$C$14:$C$5084,$A19,OUT!$D$14:$D$5084,$B19,OUT!$B$14:$B$5084,">="&$C19,OUT!$L$14:$L$5084,"<>Adjustment") -> 18 | I19: =SUMIFS(OUT!$F$14:$F$5084,OUT!$C$14:$C$5084,$A19,OUT!$D$14:$D$5084,$B19,OUT!$B$14:$B$5084,">="&$C19,OUT!$L$14:$L$5084,"<>Adjustment") -> 0.154 | J19: =SUMIFS(OUT!$E$14:$E$5084,OUT!$C$14:$C$5084,$A19,OUT!$D$14:$D$5084,$B19,OUT!$B$14:$B$5084,">="&$C19,OUT!$L$14:$L$5084,"Adjustment") -> 0 | K19: =SUMIFS(OUT!$F$14:$F$5084,OUT!$C$14:$C$5084,$A19,OUT!$D$14:$D$5084,$B19,OUT!$B$14:$B$5084,">="&$C19,OUT!$L$14:$L$5084,"Adjustment") -> 0 | L19: =D19+F19-H19-J19 -> 320 | M19: =E19+G19-I19-K19 -> 2.609775 | O19: =_xlfn.MAXIFS('OPNAME LOG'!$A$2:$A$1000,'OPNAME LOG'!$B$2:$B$1000,IF($A19="Teak","Jati",IF($A19="Pine","Pinus",$A19)),'OPNAME LOG'!$C$2:$C$1000,$B19) -> 46319 | P19: =SUMIFS('OPNAME LOG'!$D$2:$D$1000,'OPNAME LOG'!$A$2:$A$1000,$O19,'OPNAME LOG'!$B$2:$B$1000,IF($A19="Teak","Jati",IF($A19="Pine","Pinus",$A19)),'OPNAME LOG'!$C$2:$C$1000,$B19)+SUMIFS('OPNAME LOG'!$D$2:$D$1000,'OPNAME LOG'!$A$2:$A$1000,$O19,'OPNAME LOG'!$B$2:$B$1000,IF($A19="Teak","Jati",IF($A19="Pine","Pinus",$A19)),'OPNAME LOG'!$C$2:$C$1000,$B19&" (Grade A)") -> 319.84394 | Q19: =SUMIFS('OPNAME LOG'!$E$2:$E$1000,'OPNAME LOG'!$A$2:$A$1000,$O19,'OPNAME LOG'!$B$2:$B$1000,IF($A19="Teak","Jati",IF($A19="Pine","Pinus",$A19)),'OPNAME LOG'!$C$2:$C$1000,$B19)+SUMIFS('OPNAME LOG'!$E$2:$E$1000,'OPNAME LOG'!$A$2:$A$1000,$O19,'OPNAME LOG'!$B$2:$B$1000,IF($A19="Teak","Jati",IF($A19="Pine","Pinus",$A19)),'OPNAME LOG'!$C$2:$C$1000,$B19&" (Grade A)") -> 2.609775 | R19: =ROUND(L19-P19,6) -> 0.15606 | S19: =ROUND(M19-Q19,6) -> 0
A20: Sungkai | B20: 4 | C20: 46310 | D20: =SUMIFS('OPNAME LOG'!$D$2:$D$1000,'OPNAME LOG'!$A$2:$A$1000,DATE(2026,10,14),'OPNAME LOG'!$B$2:$B$1000,IF($A20="Teak","Jati",IF($A20="Pine","Pinus",$A20)),'OPNAME LOG'!$C$2:$C$1000,$B20)+SUMIFS('OPNAME LOG'!$D$2:$D$1000,'OPNAME LOG'!$A$2:$A$1000,DATE(2026,10,14),'OPNAME LOG'!$B$2:$B$1000,IF($A20="Teak","Jati",IF($A20="Pine","Pinus",$A20)),'OPNAME LOG'!$C$2:$C$1000,$B20&" (Grade A)") -> 7 | E20: =SUMIFS('OPNAME LOG'!$E$2:$E$1000,'OPNAME LOG'!$A$2:$A$1000,DATE(2026,10,14),'OPNAME LOG'!$B$2:$B$1000,IF($A20="Teak","Jati",IF($A20="Pine","Pinus",$A20)),'OPNAME LOG'!$C$2:$C$1000,$B20)+SUMIFS('OPNAME LOG'!$E$2:$E$1000,'OPNAME LOG'!$A$2:$A$1000,DATE(2026,10,14),'OPNAME LOG'!$B$2:$B$1000,IF($A20="Teak","Jati",IF($A20="Pine","Pinus",$A20)),'OPNAME LOG'!$C$2:$C$1000,$B20&" (Grade A)") -> 0.13044 | F20: =SUMIFS(INCOMING!$E$2:$E$5000,INCOMING!$C$2:$C$5000,$A20,INCOMING!$D$2:$D$5000,$B20,INCOMING!$B$2:$B$5000,">="&$C20) -> 0 | G20: =SUMIFS(INCOMING!$F$2:$F$5000,INCOMING!$C$2:$C$5000,$A20,INCOMING!$D$2:$D$5000,$B20,INCOMING!$B$2:$B$5000,">="&$C20) -> 0 | H20: =SUMIFS(OUT!$E$14:$E$5084,OUT!$C$14:$C$5084,$A20,OUT!$D$14:$D$5084,$B20,OUT!$B$14:$B$5084,">="&$C20,OUT!$L$14:$L$5084,"<>Adjustment") -> 4 | I20: =SUMIFS(OUT!$F$14:$F$5084,OUT!$C$14:$C$5084,$A20,OUT!$D$14:$D$5084,$B20,OUT!$B$14:$B$5084,">="&$C20,OUT!$L$14:$L$5084,"<>Adjustment") -> 0.04168 | J20: =SUMIFS(OUT!$E$14:$E$5084,OUT!$C$14:$C$5084,$A20,OUT!$D$14:$D$5084,$B20,OUT!$B$14:$B$5084,">="&$C20,OUT!$L$14:$L$5084,"Adjustment") -> 0 | K20: =SUMIFS(OUT!$F$14:$F$5084,OUT!$C$14:$C$5084,$A20,OUT!$D$14:$D$5084,$B20,OUT!$B$14:$B$5084,">="&$C20,OUT!$L$14:$L$5084,"Adjustment") -> 0 | L20: =D20+F20-H20-J20 -> 3 | M20: =E20+G20-I20-K20 -> 0.08876 | O20: =_xlfn.MAXIFS('OPNAME LOG'!$A$2:$A$1000,'OPNAME LOG'!$B$2:$B$1000,IF($A20="Teak","Jati",IF($A20="Pine","Pinus",$A20)),'OPNAME LOG'!$C$2:$C$1000,$B20) -> 46319 | P20: =SUMIFS('OPNAME LOG'!$D$2:$D$1000,'OPNAME LOG'!$A$2:$A$1000,$O20,'OPNAME LOG'!$B$2:$B$1000,IF($A20="Teak","Jati",IF($A20="Pine","Pinus",$A20)),'OPNAME LOG'!$C$2:$C$1000,$B20)+SUMIFS('OPNAME LOG'!$D$2:$D$1000,'OPNAME LOG'!$A$2:$A$1000,$O20,'OPNAME LOG'!$B$2:$B$1000,IF($A20="Teak","Jati",IF($A20="Pine","Pinus",$A20)),'OPNAME LOG'!$C$2:$C$1000,$B20&" (Grade A)") -> 3 | Q20: =SUMIFS('OPNAME LOG'!$E$2:$E$1000,'OPNAME LOG'!$A$2:$A$1000,$O20,'OPNAME LOG'!$B$2:$B$1000,IF($A20="Teak","Jati",IF($A20="Pine","Pinus",$A20)),'OPNAME LOG'!$C$2:$C$1000,$B20)+SUMIFS('OPNAME LOG'!$E$2:$E$1000,'OPNAME LOG'!$A$2:$A$1000,$O20,'OPNAME LOG'!$B$2:$B$1000,IF($A20="Teak","Jati",IF($A20="Pine","Pinus",$A20)),'OPNAME LOG'!$C$2:$C$1000,$B20&" (Grade A)") -> 0.08876 | R20: =ROUND(L20-P20,6) -> 0 | S20: =ROUND(M20-Q20,6) -> 0
A21: Sungkai | B21: 4.5 | C21: 46310 | D21: =SUMIFS('OPNAME LOG'!$D$2:$D$1000,'OPNAME LOG'!$A$2:$A$1000,DATE(2026,10,14),'OPNAME LOG'!$B$2:$B$1000,IF($A21="Teak","Jati",IF($A21="Pine","Pinus",$A21)),'OPNAME LOG'!$C$2:$C$1000,$B21)+SUMIFS('OPNAME LOG'!$D$2:$D$1000,'OPNAME LOG'!$A$2:$A$1000,DATE(2026,10,14),'OPNAME LOG'!$B$2:$B$1000,IF($A21="Teak","Jati",IF($A21="Pine","Pinus",$A21)),'OPNAME LOG'!$C$2:$C$1000,$B21&" (Grade A)") -> 39 | E21: =SUMIFS('OPNAME LOG'!$E$2:$E$1000,'OPNAME LOG'!$A$2:$A$1000,DATE(2026,10,14),'OPNAME LOG'!$B$2:$B$1000,IF($A21="Teak","Jati",IF($A21="Pine","Pinus",$A21)),'OPNAME LOG'!$C$2:$C$1000,$B21)+SUMIFS('OPNAME LOG'!$E$2:$E$1000,'OPNAME LOG'!$A$2:$A$1000,DATE(2026,10,14),'OPNAME LOG'!$B$2:$B$1000,IF($A21="Teak","Jati",IF($A21="Pine","Pinus",$A21)),'OPNAME LOG'!$C$2:$C$1000,$B21&" (Grade A)") -> 0.394245 | F21: =SUMIFS(INCOMING!$E$2:$E$5000,INCOMING!$C$2:$C$5000,$A21,INCOMING!$D$2:$D$5000,$B21,INCOMING!$B$2:$B$5000,">="&$C21) -> 0 | G21: =SUMIFS(INCOMING!$F$2:$F$5000,INCOMING!$C$2:$C$5000,$A21,INCOMING!$D$2:$D$5000,$B21,INCOMING!$B$2:$B$5000,">="&$C21) -> 0 | H21: =SUMIFS(OUT!$E$14:$E$5084,OUT!$C$14:$C$5084,$A21,OUT!$D$14:$D$5084,$B21,OUT!$B$14:$B$5084,">="&$C21,OUT!$L$14:$L$5084,"<>Adjustment") -> 39 | I21: =SUMIFS(OUT!$F$14:$F$5084,OUT!$C$14:$C$5084,$A21,OUT!$D$14:$D$5084,$B21,OUT!$B$14:$B$5084,">="&$C21,OUT!$L$14:$L$5084,"<>Adjustment") -> 0.388575 | J21: =SUMIFS(OUT!$E$14:$E$5084,OUT!$C$14:$C$5084,$A21,OUT!$D$14:$D$5084,$B21,OUT!$B$14:$B$5084,">="&$C21,OUT!$L$14:$L$5084,"Adjustment") -> 0 | K21: =SUMIFS(OUT!$F$14:$F$5084,OUT!$C$14:$C$5084,$A21,OUT!$D$14:$D$5084,$B21,OUT!$B$14:$B$5084,">="&$C21,OUT!$L$14:$L$5084,"Adjustment") -> 0 | L21: =D21+F21-H21-J21 -> 0 | M21: =E21+G21-I21-K21 -> 0.00567 | O21: =_xlfn.MAXIFS('OPNAME LOG'!$A$2:$A$1000,'OPNAME LOG'!$B$2:$B$1000,IF($A21="Teak","Jati",IF($A21="Pine","Pinus",$A21)),'OPNAME LOG'!$C$2:$C$1000,$B21) -> 46319 | P21: =SUMIFS('OPNAME LOG'!$D$2:$D$1000,'OPNAME LOG'!$A$2:$A$1000,$O21,'OPNAME LOG'!$B$2:$B$1000,IF($A21="Teak","Jati",IF($A21="Pine","Pinus",$A21)),'OPNAME LOG'!$C$2:$C$1000,$B21)+SUMIFS('OPNAME LOG'!$D$2:$D$1000,'OPNAME LOG'!$A$2:$A$1000,$O21,'OPNAME LOG'!$B$2:$B$1000,IF($A21="Teak","Jati",IF($A21="Pine","Pinus",$A21)),'OPNAME LOG'!$C$2:$C$1000,$B21&" (Grade A)") -> 0 | Q21: =SUMIFS('OPNAME LOG'!$E$2:$E$1000,'OPNAME LOG'!$A$2:$A$1000,$O21,'OPNAME LOG'!$B$2:$B$1000,IF($A21="Teak","Jati",IF($A21="Pine","Pinus",$A21)),'OPNAME LOG'!$C$2:$C$1000,$B21)+SUMIFS('OPNAME LOG'!$E$2:$E$1000,'OPNAME LOG'!$A$2:$A$1000,$O21,'OPNAME LOG'!$B$2:$B$1000,IF($A21="Teak","Jati",IF($A21="Pine","Pinus",$A21)),'OPNAME LOG'!$C$2:$C$1000,$B21&" (Grade A)") -> 0.00567 | R21: =ROUND(L21-P21,6) -> 0 | S21: =ROUND(M21-Q21,6) -> 0
A22: Sungkai | B22: 5 | C22: 46310 | D22: =SUMIFS('OPNAME LOG'!$D$2:$D$1000,'OPNAME LOG'!$A$2:$A$1000,DATE(2026,10,14),'OPNAME LOG'!$B$2:$B$1000,IF($A22="Teak","Jati",IF($A22="Pine","Pinus",$A22)),'OPNAME LOG'!$C$2:$C$1000,$B22)+SUMIFS('OPNAME LOG'!$D$2:$D$1000,'OPNAME LOG'!$A$2:$A$1000,DATE(2026,10,14),'OPNAME LOG'!$B$2:$B$1000,IF($A22="Teak","Jati",IF($A22="Pine","Pinus",$A22)),'OPNAME LOG'!$C$2:$C$1000,$B22&" (Grade A)") -> 43 | E22: =SUMIFS('OPNAME LOG'!$E$2:$E$1000,'OPNAME LOG'!$A$2:$A$1000,DATE(2026,10,14),'OPNAME LOG'!$B$2:$B$1000,IF($A22="Teak","Jati",IF($A22="Pine","Pinus",$A22)),'OPNAME LOG'!$C$2:$C$1000,$B22)+SUMIFS('OPNAME LOG'!$E$2:$E$1000,'OPNAME LOG'!$A$2:$A$1000,DATE(2026,10,14),'OPNAME LOG'!$B$2:$B$1000,IF($A22="Teak","Jati",IF($A22="Pine","Pinus",$A22)),'OPNAME LOG'!$C$2:$C$1000,$B22&" (Grade A)") -> 0.4283 | F22: =SUMIFS(INCOMING!$E$2:$E$5000,INCOMING!$C$2:$C$5000,$A22,INCOMING!$D$2:$D$5000,$B22,INCOMING!$B$2:$B$5000,">="&$C22) -> 0 | G22: =SUMIFS(INCOMING!$F$2:$F$5000,INCOMING!$C$2:$C$5000,$A22,INCOMING!$D$2:$D$5000,$B22,INCOMING!$B$2:$B$5000,">="&$C22) -> 0 | H22: =SUMIFS(OUT!$E$14:$E$5084,OUT!$C$14:$C$5084,$A22,OUT!$D$14:$D$5084,$B22,OUT!$B$14:$B$5084,">="&$C22,OUT!$L$14:$L$5084,"<>Adjustment") -> 36 | I22: =SUMIFS(OUT!$F$14:$F$5084,OUT!$C$14:$C$5084,$A22,OUT!$D$14:$D$5084,$B22,OUT!$B$14:$B$5084,">="&$C22,OUT!$L$14:$L$5084,"<>Adjustment") -> 0.353645 | J22: =SUMIFS(OUT!$E$14:$E$5084,OUT!$C$14:$C$5084,$A22,OUT!$D$14:$D$5084,$B22,OUT!$B$14:$B$5084,">="&$C22,OUT!$L$14:$L$5084,"Adjustment") -> 0 | K22: =SUMIFS(OUT!$F$14:$F$5084,OUT!$C$14:$C$5084,$A22,OUT!$D$14:$D$5084,$B22,OUT!$B$14:$B$5084,">="&$C22,OUT!$L$14:$L$5084,"Adjustment") -> 0 | L22: =D22+F22-H22-J22 -> 7 | M22: =E22+G22-I22-K22 -> 0.074655 | O22: =_xlfn.MAXIFS('OPNAME LOG'!$A$2:$A$1000,'OPNAME LOG'!$B$2:$B$1000,IF($A22="Teak","Jati",IF($A22="Pine","Pinus",$A22)),'OPNAME LOG'!$C$2:$C$1000,$B22) -> 46319 | P22: =SUMIFS('OPNAME LOG'!$D$2:$D$1000,'OPNAME LOG'!$A$2:$A$1000,$O22,'OPNAME LOG'!$B$2:$B$1000,IF($A22="Teak","Jati",IF($A22="Pine","Pinus",$A22)),'OPNAME LOG'!$C$2:$C$1000,$B22)+SUMIFS('OPNAME LOG'!$D$2:$D$1000,'OPNAME LOG'!$A$2:$A$1000,$O22,'OPNAME LOG'!$B$2:$B$1000,IF($A22="Teak","Jati",IF($A22="Pine","Pinus",$A22)),'OPNAME LOG'!$C$2:$C$1000,$B22&" (Grade A)") -> 7 | Q22: =SUMIFS('OPNAME LOG'!$E$2:$E$1000,'OPNAME LOG'!$A$2:$A$1000,$O22,'OPNAME LOG'!$B$2:$B$1000,IF($A22="Teak","Jati",IF($A22="Pine","Pinus",$A22)),'OPNAME LOG'!$C$2:$C$1000,$B22)+SUMIFS('OPNAME LOG'!$E$2:$E$1000,'OPNAME LOG'!$A$2:$A$1000,$O22,'OPNAME LOG'!$B$2:$B$1000,IF($A22="Teak","Jati",IF($A22="Pine","Pinus",$A22)),'OPNAME LOG'!$C$2:$C$1000,$B22&" (Grade A)") -> 0.074655 | R22: =ROUND(L22-P22,6) -> 0 | S22: =ROUND(M22-Q22,6) -> 0
A23: Sungkai | B23: 5.5 | C23: 46310 | D23: =SUMIFS('OPNAME LOG'!$D$2:$D$1000,'OPNAME LOG'!$A$2:$A$1000,DATE(2026,10,14),'OPNAME LOG'!$B$2:$B$1000,IF($A23="Teak","Jati",IF($A23="Pine","Pinus",$A23)),'OPNAME LOG'!$C$2:$C$1000,$B23)+SUMIFS('OPNAME LOG'!$D$2:$D$1000,'OPNAME LOG'!$A$2:$A$1000,DATE(2026,10,14),'OPNAME LOG'!$B$2:$B$1000,IF($A23="Teak","Jati",IF($A23="Pine","Pinus",$A23)),'OPNAME LOG'!$C$2:$C$1000,$B23&" (Grade A)") -> 34 | E23: =SUMIFS('OPNAME LOG'!$E$2:$E$1000,'OPNAME LOG'!$A$2:$A$1000,DATE(2026,10,14),'OPNAME LOG'!$B$2:$B$1000,IF($A23="Teak","Jati",IF($A23="Pine","Pinus",$A23)),'OPNAME LOG'!$C$2:$C$1000,$B23)+SUMIFS('OPNAME LOG'!$E$2:$E$1000,'OPNAME LOG'!$A$2:$A$1000,DATE(2026,10,14),'OPNAME LOG'!$B$2:$B$1000,IF($A23="Teak","Jati",IF($A23="Pine","Pinus",$A23)),'OPNAME LOG'!$C$2:$C$1000,$B23&" (Grade A)") -> 0.400015 | F23: =SUMIFS(INCOMING!$E$2:$E$5000,INCOMING!$C$2:$C$5000,$A23,INCOMING!$D$2:$D$5000,$B23,INCOMING!$B$2:$B$5000,">="&$C23) -> 0 | G23: =SUMIFS(INCOMING!$F$2:$F$5000,INCOMING!$C$2:$C$5000,$A23,INCOMING!$D$2:$D$5000,$B23,INCOMING!$B$2:$B$5000,">="&$C23) -> 0 | H23: =SUMIFS(OUT!$E$14:$E$5084,OUT!$C$14:$C$5084,$A23,OUT!$D$14:$D$5084,$B23,OUT!$B$14:$B$5084,">="&$C23,OUT!$L$14:$L$5084,"<>Adjustment") -> 24 | I23: =SUMIFS(OUT!$F$14:$F$5084,OUT!$C$14:$C$5084,$A23,OUT!$D$14:$D$5084,$B23,OUT!$B$14:$B$5084,">="&$C23,OUT!$L$14:$L$5084,"<>Adjustment") -> 0.294965 | J23: =SUMIFS(OUT!$E$14:$E$5084,OUT!$C$14:$C$5084,$A23,OUT!$D$14:$D$5084,$B23,OUT!$B$14:$B$5084,">="&$C23,OUT!$L$14:$L$5084,"Adjustment") -> 0 | K23: =SUMIFS(OUT!$F$14:$F$5084,OUT!$C$14:$C$5084,$A23,OUT!$D$14:$D$5084,$B23,OUT!$B$14:$B$5084,">="&$C23,OUT!$L$14:$L$5084,"Adjustment") -> 0 | L23: =D23+F23-H23-J23 -> 10 | M23: =E23+G23-I23-K23 -> 0.10505 | O23: =_xlfn.MAXIFS('OPNAME LOG'!$A$2:$A$1000,'OPNAME LOG'!$B$2:$B$1000,IF($A23="Teak","Jati",IF($A23="Pine","Pinus",$A23)),'OPNAME LOG'!$C$2:$C$1000,$B23) -> 46319 | P23: =SUMIFS('OPNAME LOG'!$D$2:$D$1000,'OPNAME LOG'!$A$2:$A$1000,$O23,'OPNAME LOG'!$B$2:$B$1000,IF($A23="Teak","Jati",IF($A23="Pine","Pinus",$A23)),'OPNAME LOG'!$C$2:$C$1000,$B23)+SUMIFS('OPNAME LOG'!$D$2:$D$1000,'OPNAME LOG'!$A$2:$A$1000,$O23,'OPNAME LOG'!$B$2:$B$1000,IF($A23="Teak","Jati",IF($A23="Pine","Pinus",$A23)),'OPNAME LOG'!$C$2:$C$1000,$B23&" (Grade A)") -> 10 | Q23: =SUMIFS('OPNAME LOG'!$E$2:$E$1000,'OPNAME LOG'!$A$2:$A$1000,$O23,'OPNAME LOG'!$B$2:$B$1000,IF($A23="Teak","Jati",IF($A23="Pine","Pinus",$A23)),'OPNAME LOG'!$C$2:$C$1000,$B23)+SUMIFS('OPNAME LOG'!$E$2:$E$1000,'OPNAME LOG'!$A$2:$A$1000,$O23,'OPNAME LOG'!$B$2:$B$1000,IF($A23="Teak","Jati",IF($A23="Pine","Pinus",$A23)),'OPNAME LOG'!$C$2:$C$1000,$B23&" (Grade A)") -> 0.10505 | R23: =ROUND(L23-P23,6) -> 0 | S23: =ROUND(M23-Q23,6) -> 0
A24: Sungkai | B24: 7.5 | C24: 46310 | D24: =SUMIFS('OPNAME LOG'!$D$2:$D$1000,'OPNAME LOG'!$A$2:$A$1000,DATE(2026,10,14),'OPNAME LOG'!$B$2:$B$1000,IF($A24="Teak","Jati",IF($A24="Pine","Pinus",$A24)),'OPNAME LOG'!$C$2:$C$1000,$B24)+SUMIFS('OPNAME LOG'!$D$2:$D$1000,'OPNAME LOG'!$A$2:$A$1000,DATE(2026,10,14),'OPNAME LOG'!$B$2:$B$1000,IF($A24="Teak","Jati",IF($A24="Pine","Pinus",$A24)),'OPNAME LOG'!$C$2:$C$1000,$B24&" (Grade A)") -> 127 | E24: =SUMIFS('OPNAME LOG'!$E$2:$E$1000,'OPNAME LOG'!$A$2:$A$1000,DATE(2026,10,14),'OPNAME LOG'!$B$2:$B$1000,IF($A24="Teak","Jati",IF($A24="Pine","Pinus",$A24)),'OPNAME LOG'!$C$2:$C$1000,$B24)+SUMIFS('OPNAME LOG'!$E$2:$E$1000,'OPNAME LOG'!$A$2:$A$1000,DATE(2026,10,14),'OPNAME LOG'!$B$2:$B$1000,IF($A24="Teak","Jati",IF($A24="Pine","Pinus",$A24)),'OPNAME LOG'!$C$2:$C$1000,$B24&" (Grade A)") -> 2.71845 | F24: =SUMIFS(INCOMING!$E$2:$E$5000,INCOMING!$C$2:$C$5000,$A24,INCOMING!$D$2:$D$5000,$B24,INCOMING!$B$2:$B$5000,">="&$C24) -> 0 | G24: =SUMIFS(INCOMING!$F$2:$F$5000,INCOMING!$C$2:$C$5000,$A24,INCOMING!$D$2:$D$5000,$B24,INCOMING!$B$2:$B$5000,">="&$C24) -> 0 | H24: =SUMIFS(OUT!$E$14:$E$5084,OUT!$C$14:$C$5084,$A24,OUT!$D$14:$D$5084,$B24,OUT!$B$14:$B$5084,">="&$C24,OUT!$L$14:$L$5084,"<>Adjustment") -> 25 | I24: =SUMIFS(OUT!$F$14:$F$5084,OUT!$C$14:$C$5084,$A24,OUT!$D$14:$D$5084,$B24,OUT!$B$14:$B$5084,">="&$C24,OUT!$L$14:$L$5084,"<>Adjustment") -> 0.680625 | J24: =SUMIFS(OUT!$E$14:$E$5084,OUT!$C$14:$C$5084,$A24,OUT!$D$14:$D$5084,$B24,OUT!$B$14:$B$5084,">="&$C24,OUT!$L$14:$L$5084,"Adjustment") -> 0 | K24: =SUMIFS(OUT!$F$14:$F$5084,OUT!$C$14:$C$5084,$A24,OUT!$D$14:$D$5084,$B24,OUT!$B$14:$B$5084,">="&$C24,OUT!$L$14:$L$5084,"Adjustment") -> 0 | L24: =D24+F24-H24-J24 -> 102 | M24: =E24+G24-I24-K24 -> 2.037825 | O24: =_xlfn.MAXIFS('OPNAME LOG'!$A$2:$A$1000,'OPNAME LOG'!$B$2:$B$1000,IF($A24="Teak","Jati",IF($A24="Pine","Pinus",$A24)),'OPNAME LOG'!$C$2:$C$1000,$B24) -> 46319 | P24: =SUMIFS('OPNAME LOG'!$D$2:$D$1000,'OPNAME LOG'!$A$2:$A$1000,$O24,'OPNAME LOG'!$B$2:$B$1000,IF($A24="Teak","Jati",IF($A24="Pine","Pinus",$A24)),'OPNAME LOG'!$C$2:$C$1000,$B24)+SUMIFS('OPNAME LOG'!$D$2:$D$1000,'OPNAME LOG'!$A$2:$A$1000,$O24,'OPNAME LOG'!$B$2:$B$1000,IF($A24="Teak","Jati",IF($A24="Pine","Pinus",$A24)),'OPNAME LOG'!$C$2:$C$1000,$B24&" (Grade A)") -> 102 | Q24: =SUMIFS('OPNAME LOG'!$E$2:$E$1000,'OPNAME LOG'!$A$2:$A$1000,$O24,'OPNAME LOG'!$B$2:$B$1000,IF($A24="Teak","Jati",IF($A24="Pine","Pinus",$A24)),'OPNAME LOG'!$C$2:$C$1000,$B24)+SUMIFS('OPNAME LOG'!$E$2:$E$1000,'OPNAME LOG'!$A$2:$A$1000,$O24,'OPNAME LOG'!$B$2:$B$1000,IF($A24="Teak","Jati",IF($A24="Pine","Pinus",$A24)),'OPNAME LOG'!$C$2:$C$1000,$B24&" (Grade A)") -> 2.037825 | R24: =ROUND(L24-P24,6) -> 0 | S24: =ROUND(M24-Q24,6) -> 0
A25: Sungkai | B25: 8 | C25: 46310 | D25: =SUMIFS('OPNAME LOG'!$D$2:$D$1000,'OPNAME LOG'!$A$2:$A$1000,DATE(2026,10,14),'OPNAME LOG'!$B$2:$B$1000,IF($A25="Teak","Jati",IF($A25="Pine","Pinus",$A25)),'OPNAME LOG'!$C$2:$C$1000,$B25)+SUMIFS('OPNAME LOG'!$D$2:$D$1000,'OPNAME LOG'!$A$2:$A$1000,DATE(2026,10,14),'OPNAME LOG'!$B$2:$B$1000,IF($A25="Teak","Jati",IF($A25="Pine","Pinus",$A25)),'OPNAME LOG'!$C$2:$C$1000,$B25&" (Grade A)") -> 165 | E25: =SUMIFS('OPNAME LOG'!$E$2:$E$1000,'OPNAME LOG'!$A$2:$A$1000,DATE(2026,10,14),'OPNAME LOG'!$B$2:$B$1000,IF($A25="Teak","Jati",IF($A25="Pine","Pinus",$A25)),'OPNAME LOG'!$C$2:$C$1000,$B25)+SUMIFS('OPNAME LOG'!$E$2:$E$1000,'OPNAME LOG'!$A$2:$A$1000,DATE(2026,10,14),'OPNAME LOG'!$B$2:$B$1000,IF($A25="Teak","Jati",IF($A25="Pine","Pinus",$A25)),'OPNAME LOG'!$C$2:$C$1000,$B25&" (Grade A)") -> 3.76424 | F25: =SUMIFS(INCOMING!$E$2:$E$5000,INCOMING!$C$2:$C$5000,$A25,INCOMING!$D$2:$D$5000,$B25,INCOMING!$B$2:$B$5000,">="&$C25) -> 0 | G25: =SUMIFS(INCOMING!$F$2:$F$5000,INCOMING!$C$2:$C$5000,$A25,INCOMING!$D$2:$D$5000,$B25,INCOMING!$B$2:$B$5000,">="&$C25) -> 0 | H25: =SUMIFS(OUT!$E$14:$E$5084,OUT!$C$14:$C$5084,$A25,OUT!$D$14:$D$5084,$B25,OUT!$B$14:$B$5084,">="&$C25,OUT!$L$14:$L$5084,"<>Adjustment") -> 9 | I25: =SUMIFS(OUT!$F$14:$F$5084,OUT!$C$14:$C$5084,$A25,OUT!$D$14:$D$5084,$B25,OUT!$B$14:$B$5084,">="&$C25,OUT!$L$14:$L$5084,"<>Adjustment") -> 0.22136 | J25: =SUMIFS(OUT!$E$14:$E$5084,OUT!$C$14:$C$5084,$A25,OUT!$D$14:$D$5084,$B25,OUT!$B$14:$B$5084,">="&$C25,OUT!$L$14:$L$5084,"Adjustment") -> 0 | K25: =SUMIFS(OUT!$F$14:$F$5084,OUT!$C$14:$C$5084,$A25,OUT!$D$14:$D$5084,$B25,OUT!$B$14:$B$5084,">="&$C25,OUT!$L$14:$L$5084,"Adjustment") -> 0 | L25: =D25+F25-H25-J25 -> 156 | M25: =E25+G25-I25-K25 -> 3.54288 | O25: =_xlfn.MAXIFS('OPNAME LOG'!$A$2:$A$1000,'OPNAME LOG'!$B$2:$B$1000,IF($A25="Teak","Jati",IF($A25="Pine","Pinus",$A25)),'OPNAME LOG'!$C$2:$C$1000,$B25) -> 46319 | P25: =SUMIFS('OPNAME LOG'!$D$2:$D$1000,'OPNAME LOG'!$A$2:$A$1000,$O25,'OPNAME LOG'!$B$2:$B$1000,IF($A25="Teak","Jati",IF($A25="Pine","Pinus",$A25)),'OPNAME LOG'!$C$2:$C$1000,$B25)+SUMIFS('OPNAME LOG'!$D$2:$D$1000,'OPNAME LOG'!$A$2:$A$1000,$O25,'OPNAME LOG'!$B$2:$B$1000,IF($A25="Teak","Jati",IF($A25="Pine","Pinus",$A25)),'OPNAME LOG'!$C$2:$C$1000,$B25&" (Grade A)") -> 156 | Q25: =SUMIFS('OPNAME LOG'!$E$2:$E$1000,'OPNAME LOG'!$A$2:$A$1000,$O25,'OPNAME LOG'!$B$2:$B$1000,IF($A25="Teak","Jati",IF($A25="Pine","Pinus",$A25)),'OPNAME LOG'!$C$2:$C$1000,$B25)+SUMIFS('OPNAME LOG'!$E$2:$E$1000,'OPNAME LOG'!$A$2:$A$1000,$O25,'OPNAME LOG'!$B$2:$B$1000,IF($A25="Teak","Jati",IF($A25="Pine","Pinus",$A25)),'OPNAME LOG'!$C$2:$C$1000,$B25&" (Grade A)") -> 3.54288 | R25: =ROUND(L25-P25,6) -> 0 | S25: =ROUND(M25-Q25,6) -> 0
A26: Total Sungkai | D26: =SUM(D17:D25) -> 1071 | E26: =SUM(E17:E25) -> 12.372561 | F26: =SUM(F17:F25) -> 0 | G26: =SUM(G17:G25) -> 0 | H26: =SUM(H17:H25) -> 200 | I26: =SUM(I17:I25) -> 2.44244 | J26: =SUM(J17:J25) -> 0 | K26: =SUM(K17:K25) -> 0 | ... M26: =SUM(M17:M25) -> 9.930121 | P26: =SUM(P17:P25) -> 870.72748 | Q26: =SUM(Q17:Q25) -> 9.930121 | R26: =SUM(R17:R25) -> 0.27252 | S26: =SUM(S17:S25) -> 0
